Starting continuous runner...
Press Ctrl+C to stop
Running main_api.py at 2025-10-25 23:15:31
Starting continuous runner...
Press Ctrl+C to stop
Running main_api.py at 2025-10-25 23:16:12
Output: Her şey iyi mi?

Return code: 0
Running main_api.py at 2025-10-25 23:16:24
Output: İyi bir deneme yaptın!

Return code: 0
Running main_api.py at 2025-10-25 23:16:37
Output: Bir şeyler deneyeceksin mi? Ne hakkında?

Return code: 0
Running main_api.py at 2025-10-25 23:16:49
Output: Denemede ne yapmak istiyorsun?

Return code: 0
Running main_api.py at 2025-10-25 23:17:02
Output: Bu kelimeyle ne yapmak istiyorsun?

Return code: 0
Running main_api.py at 2025-10-25 23:17:14
Output: Ne için deneme yapacaksın?

Return code: 0
Running main_api.py at 2025-10-25 23:17:26
Output: İyi misin?

Return code: 0
Running main_api.py at 2025-10-25 23:17:39
Output: Denemeler için ne ihtiyacın var?

Return code: 0
Running main_api.py at 2025-10-25 23:17:51
Output: İyiyim. Size ne yardımcı olabilirim?

Return code: 0
Starting continuous runner...
Press Ctrl+C to stop
Running main_api.py at 2025-10-25 23:17:55
Output: Denemeye devam edelim! Ne hakkında konuşmak istersin?

Return code: 0
Running main_api.py at 2025-10-25 23:18:08
Output: Herhangi bir şey denemek istiyorsun mu?

Return code: 0
Running main_api.py at 2025-10-25 23:18:20
Output: İyi bir gün diliyorum.

Return code: 0
Running main_api.py at 2025-10-25 23:18:33
Output: Deneme yapmayı istiyorsun sanırım! Ne tür bir deneme yapmak istersin? Bir oyun, bir test, ya da başka bir şey?

Return code: 0
Running main_api.py at 2025-10-25 23:18:45
Output: Denemelerinizi yapabilirsiniz.

Return code: 0
Running main_api.py at 2025-10-25 23:18:58
Output: İyi bir gün dilerim. Ne için deneme yapıyorsun?

Return code: 0
Running main_api.py at 2025-10-25 23:19:11
Output: İçeriği hakkında bilgi vermem gerekiyor. Lütfen daha fazla ayrıntı isteyeyim.

Return code: 0
Running main_api.py at 2025-10-25 23:19:23
Output: Denemeler için ne yapmak istiyorsun?

Return code: 0
Running main_api.py at 2025-10-25 23:19:37
Output: İçerik oluşturuyorsanız, denemeye başlamak için neye ihtiyacınız olduğunu bilmek isteyebilirsiniz. İşte bazı adımlar:

1. **Konuyu belirleyin**: Bir konuya odaklanmak, yazmaya başlamanızı kolaylaştıracaktır.
2. **Amaç belirleyin**: Yazacağınız metnin türü (makale, hikaye, inceleme vb.) ve amacı ne olursa olsun, bunu bilinerek yazabilirsiniz.
3. **Plan oluşturun**: Konuyu ve amaçları düşünün, sonra başlıkları ve ana noktaları listeleyin.
4. **Yazmaya başlayın**: Planınızı uygulayın ve yazmaya başlayın.
5. **Düzenle ve kontrol edin**: Yazdıktan sonra metni kontrol edin ve düzeltin.

Denemelerinizden iyi şeyler umuyorum!

Return code: 0
Running main_api.py at 2025-10-25 23:19:50
Output: Herhangi bir şey için denemeniz mi gerekiyor? Yardıma nasıl ihtiyacım var?

Return code: 0
Running main_api.py at 2025-10-25 23:20:02
Output: İçerik oluşturuyorsun galiba.

Return code: 0
Running main_api.py at 2025-10-25 23:20:15
Output: Hiçbir şey yazmadığın için, denemenin ne anlama geldiğini bilmiyorum. Lütfen daha fazla bilgi vermenizi isteyeceğim.

Return code: 0
Running main_api.py at 2025-10-25 23:20:27
Output: Herhangi bir şey söylemek ister misiniz?

Return code: 0
Running main_api.py at 2025-10-25 23:20:39
Output: Denemeler yapmaktan keyif alıyorsanız, bana ne tür bir deneme yapmak istiyorsunuz? Bir oyun oynamak, bir kelime bulmacası çözmek, veya başka bir şey mi?

Return code: 0
Running main_api.py at 2025-10-25 23:20:52
Output: Herhangi bir şey denemek istiyorsanız, lütfen bana ne istediğinizi söyleyin. Ben size yardımcı olmaya hazırım!

Return code: 0
Running main_api.py at 2025-10-25 23:21:05
Output: Denemeler yapmak ve yeni şeyler denemek her zaman faydalıdır. Deneyimlerimizle birlikte gelişir, yeni bilgiler edinebilir ve daha iyi kararlar verebiliriz. Hangi alanda deneyeceğinizi söyleyebilir misiniz?

Return code: 0
Running main_api.py at 2025-10-25 23:21:18
Output: Her şey iyi mi? Denemeye ne için geldin?

Return code: 0
Running main_api.py at 2025-10-25 23:21:30
Output: Deneme yapılıyor.

Return code: 0
Running main_api.py at 2025-10-25 23:21:42
Output: Denemelerde ne iş yaptığını göstermek önemlidir.

Return code: 0
Running main_api.py at 2025-10-25 23:21:54
Output: Daha fazla bilgi için ne yapmak istiyorsanız bana sorabilirsiniz.

Return code: 0
Running main_api.py at 2025-10-25 23:22:07
Output: Denemeler! Bu size ne yardımcı olabilir? Size bir soru sorabilir miyim?

Return code: 0
Running main_api.py at 2025-10-25 23:22:19
Output: Deneme yapmak istiyorsanız, neyin denemesi gerektiğini söylemeliyim. Deneme yapacağınız şey bir kelime oyunu olabilir. Kelime oyunları birçok farklı türde olabilir. Bunlardan bazıları şunlardır:

1. Anagram: Bir kelimenin harflerini karıştırarak oluşturulan yeni bir kelime.
2. Kelime Bulma: Bir gruba verilen kelimelerden hangisinin bir diğerine ne kadar benzeyebileceğini bulmak.
3. Kelime Çözme: Bir kelimenin ne anlama geldiğini veya hangi kelimeye benzediğini bulmak.

Bu oyunlar ve daha birçok farklı türde kelime oyunu deneme yapabilirsiniz.

Return code: 0
Running main_api.py at 2025-10-25 23:22:32
Output: Denemeler için ne yapmak istiyorsunuz?

Return code: 0
Running main_api.py at 2025-10-25 23:22:45
Output: Denemeler için ne yapabilirim derseniz, size birkaç örnek verebilirim:

1. **Yazılım Geliştirme**: Benimle birlikte bir uygulamanın özeti yazabilir, özelliklerini tartışabiliriz.
2. **Sözlük Öğrenme**: Bir kelime seçer ve onun anlamını öğrenir, pratik yapabilirsiniz.
3. **Matematik Problemleri Çözme**: Matematik problemi verip birlikte çözerek pratik yapabilirsiniz.

Hangi deneme türünü yapmak istersiniz?

Return code: 0
Running main_api.py at 2025-10-25 23:22:58
Output: Denemeler yapmak için ne tür bir şey istiyorsunuz?

Return code: 0
Running main_api.py at 2025-10-25 23:23:10
Output: İyi misin?

Return code: 0
Running main_api.py at 2025-10-25 23:23:22
Output: Denemeler için ne yapmak istiyorsunuz?

Return code: 0
Running main_api.py at 2025-10-25 23:23:34
Output: İyi bir deneme olsun umuduyla... Ne tür bir denemenin yapılmasını istiyorsunuz? Bir konuyu tartışmak, oyun oynamak, bir sorunun cevabı aramak veya başka bir şey?

Return code: 0
Running main_api.py at 2025-10-25 23:23:48
Output: İyi bir deneme yaptın! Deneme yapmak, yeni şeyler deneyerek ve öğrenmek için fırsatlar aramak önemli. Peki, ne hakkında deneme yapacaksın?

Return code: 0
Running main_api.py at 2025-10-25 23:24:00
Output: İyi bir deneme yaptın! Deneme yapmayı seviyor musun?

Return code: 0
Running main_api.py at 2025-10-25 23:24:12
Output: Denemeler için hazırım. Ne hakkında sorular sormak istersin?

Return code: 0
Running main_api.py at 2025-10-25 23:24:25
Output: İyi bir deneme olsun umuyorum. Ne hakkında denemiş olabilirsin?

Return code: 0
Running main_api.py at 2025-10-25 23:24:38
Output: Bu bir deneme mi?

Return code: 0
Running main_api.py at 2025-10-25 23:24:50
Output: Ne için deneme yapıyorsun?

Return code: 0
Running main_api.py at 2025-10-25 23:25:02
Output: Ne yapmak istiyorsun?

Return code: 0
Running main_api.py at 2025-10-25 23:25:15
Output: Herhangi bir konu hakkında bilgi mi istiyorsunuz?

Return code: 0
Running main_api.py at 2025-10-25 23:25:27
Output: Denemeler için buradayım! Ne hakkında bilgi istiyorsun?

Return code: 0
Running main_api.py at 2025-10-25 23:25:39
Output: İyiyim. Nasıl oluyorsun?

Return code: 0
Running main_api.py at 2025-10-25 23:25:52
Output: İyi bir deneme oldu mu?

Return code: 0
Running main_api.py at 2025-10-25 23:26:04
Output: Herhangi bir şey denemek için buradasın. Benimle ne yapabilirsin?

Return code: 0
Running main_api.py at 2025-10-25 23:26:16
Output: Denemeler için ne yapabiliriz? Bir oyun oynamak istiyorsanız, bir kelime bulmacası çözmemizi isteyebilirsiniz. İsterseniz bir konuya göre bilgi edinebilir ve sorularınızı yanıtlamaya çalışırım.

Return code: 0
Running main_api.py at 2025-10-25 23:26:29
Output: İçinde ne olduğunu bilmiyorum. Bir şey denemek istiyorsan bana söyle.

Return code: 0
Running main_api.py at 2025-10-25 23:26:41
Output: İyi mi?

Return code: 0
Running main_api.py at 2025-10-25 23:26:53
Output: Hiç bir şey söylemiyorum! Denemen ne için?

Return code: 0
Running main_api.py at 2025-10-25 23:27:05
Output: Bir şeyler denemek istiyorsun sanırım! Ne tür bir denemenin içinde olacaksın? Bir oyun, bir soruluk veya sadece konuşmak isteyebilirsin. Ben seninle her türlü konuyu tartışmaya açıkım!

Return code: 0
Running main_api.py at 2025-10-25 23:27:18
Output: Herhangi bir şey denemek istiyorsan, neler yapmak istersin?

Return code: 0
Running main_api.py at 2025-10-25 23:27:30
Output: Denemeler! Ne tür bir deneme yapmak istiyorsunuz? Bir soru sorabilir miyim?

Return code: 0
Running main_api.py at 2025-10-25 23:27:42
Output: Denemede ne yapmak istiyorsun?

Return code: 0
Running main_api.py at 2025-10-25 23:28:00
Output: İyiyim.

Return code: 0
Running main_api.py at 2025-10-25 23:28:12
Output: Ne yapmak istiyorsun?

Return code: 0
Running main_api.py at 2025-10-25 23:28:24
Output: Denemen ne zaman?

Return code: 0
Running main_api.py at 2025-10-25 23:28:36
Output: Denemelerde ne yapmak istiyorsun?

Return code: 0
Running main_api.py at 2025-10-25 23:28:49
Output: İyi günler dilerim! Denemeye ne için geldin?

Return code: 0
Running main_api.py at 2025-10-25 23:29:02
Output: Denemeler için ne yapabilirsiniz?

1. Bir kelime oyunu oynayabilir, örneğin "kelime" ile başlayan bir kelime bulma oyunu.
2. Bir şiir veya hikaye yazabilirsiniz.
3. Bir soruyla başlamanız ve bir cevapla bitmenizi sağlayacak bir deneme yapabilirsiniz.
4. Bir kelimeyi veya terimi açıklamaya çalışabilirsiniz.
5. Bir hikayeyi anlatarak okuyuculara hissettirmek için denemeler yapabilirsiniz.

Denemeler, yaratıcılık ve düşünceyi geliştirmek için kullanışlı olabilir.

Return code: 0
Running main_api.py at 2025-10-25 23:29:16
Output: İyi bir deneme yaptın. Deneme yapabilir misin?

Return code: 0
Running main_api.py at 2025-10-25 23:29:28
Output: Denemeler için hoş geldiniz! Ne hakkında bilgi arıyorsunuz?

Return code: 0
Running main_api.py at 2025-10-25 23:29:40
Output: Ne için deneme yapıyorsun?

Return code: 0
Running main_api.py at 2025-10-25 23:29:53
Output: İyi bir deneme! Ne hakkında denemiştin?

Return code: 0
Running main_api.py at 2025-10-25 23:30:05
Output: Ne yapmayı planlıyorsun?

Return code: 0
Running main_api.py at 2025-10-25 23:30:17
Output: İyiyim, size ne yardımcı olabilirim?

Return code: 0
Running main_api.py at 2025-10-25 23:30:31
Output: Herhangi bir şey denemek için buradayım. Ne istersen yapabiliriz!

Return code: 0
Running main_api.py at 2025-10-25 23:30:43
Output: Ne yapılabilir?

Return code: 0
Running main_api.py at 2025-10-25 23:30:56
Output: Anlamı ne? Deneme, deneyerek anlamaya çalışmak.

Return code: 0
Running main_api.py at 2025-10-25 23:31:08
Output: İlerleyen adımlar için daha fazla bilgiye ihtiyacım var. Lütfen bir soru sorabilir veya konuyu açıklamak isteyebilirsiniz.

Return code: 0
Running main_api.py at 2025-10-25 23:31:20
Output: İyiyim, teşekkür ederim. size ne yardımcı olabilirim?

Return code: 0
Running main_api.py at 2025-10-25 23:31:33
Output: Denemeler! Ne tür bir deneme yapmak istiyorsunuz? Bir oyun, bir soruluk veya sadece konuşmak için mi?

Return code: 0
Running main_api.py at 2025-10-25 23:31:45
Output: Ne için deneme yapıyorsun?

Return code: 0
Running main_api.py at 2025-10-25 23:31:57
Output: Ne için deneme yapıyorsun?

Return code: 0
Running main_api.py at 2025-10-25 23:32:10
Output: Denemen ne zaman?

Return code: 0
Running main_api.py at 2025-10-25 23:32:22
Output: Denemeler için ne yapmak istiyorsun?

Return code: 0
Running main_api.py at 2025-10-25 23:32:35
Output: İyi bir deneme! Ne hakkında denemiştin?

Return code: 0
Running main_api.py at 2025-10-25 23:32:48
Output: Ne yapmak istiyorsun?

Return code: 0
Running main_api.py at 2025-10-25 23:33:01
Output: Herhangi bir konudan bahsetmek ister misin?

Return code: 0
Running main_api.py at 2025-10-25 23:33:13
Error: Traceback (most recent call last):
  File "/Users/utkan.basurgan/Main/1. Works Files/2. Gits Works/Zenarth-Meta-Hackathon-2025/APP_Api/python_api.py", line 42, in connect_ssh
    client.connect(
    ~~~~~~~~~~~~~~^
        hostname=host,
        ^^^^^^^^^^^^^^
    ...<5 lines>...
        look_for_keys=False,
        ^^^^^^^^^^^^^^^^^^^^
    )
    ^
  File "/Users/utkan.basurgan/Main/1. Works Files/2. Gits Works/Zenarth-Meta-Hackathon-2025/APP_Api/venv/lib/python3.14/site-packages/paramiko/client.py", line 384, in connect
    sock.connect(addr)
    ~~~~~~~~~~~~^^^^^^
OSError: [Errno 51] Network is unreachable

During handling of the above exception, another exception occurred:

Traceback (most recent call last):
  File "/Users/utkan.basurgan/Main/1. Works Files/2. Gits Works/Zenarth-Meta-Hackathon-2025/APP_Api/main_api.py", line 26, in <module>
    ssh = connect_ssh(HOST, PORT, USER, KEY_PATH, PASSFILE_PATH)
  File "/Users/utkan.basurgan/Main/1. Works Files/2. Gits Works/Zenarth-Meta-Hackathon-2025/APP_Api/python_api.py", line 52, in connect_ssh
    raise RuntimeError(f"SSH bağlantı hatası: {e}")
RuntimeError: SSH bağlantı hatası: [Errno 51] Network is unreachable

Return code: 1
Running main_api.py at 2025-10-25 23:33:27
Error: Exception (client): Error reading SSH protocol banner
Traceback (most recent call last):
  File "/Users/utkan.basurgan/Main/1. Works Files/2. Gits Works/Zenarth-Meta-Hackathon-2025/APP_Api/venv/lib/python3.14/site-packages/paramiko/transport.py", line 2363, in _check_banner
    buf = self.packetizer.readline(timeout)
  File "/Users/utkan.basurgan/Main/1. Works Files/2. Gits Works/Zenarth-Meta-Hackathon-2025/APP_Api/venv/lib/python3.14/site-packages/paramiko/packet.py", line 395, in readline
    buf += self._read_timeout(timeout)
           ~~~~~~~~~~~~~~~~~~^^^^^^^^^
  File "/Users/utkan.basurgan/Main/1. Works Files/2. Gits Works/Zenarth-Meta-Hackathon-2025/APP_Api/venv/lib/python3.14/site-packages/paramiko/packet.py", line 673, in _read_timeout
    raise socket.timeout()
TimeoutError

During handling of the above exception, another exception occurred:

Traceback (most recent call last):
  File "/Users/utkan.basurgan/Main/1. Works Files/2. Gits Works/Zenarth-Meta-Hackathon-2025/APP_Api/venv/lib/python3.14/site-packages/paramiko/transport.py", line 2179, in run
    self._check_banner()
    ~~~~~~~~~~~~~~~~~~^^
  File "/Users/utkan.basurgan/Main/1. Works Files/2. Gits Works/Zenarth-Meta-Hackathon-2025/APP_Api/venv/lib/python3.14/site-packages/paramiko/transport.py", line 2367, in _check_banner
    raise SSHException(
        "Error reading SSH protocol banner" + str(e)
    )
paramiko.ssh_exception.SSHException: Error reading SSH protocol banner

Traceback (most recent call last):
  File "/Users/utkan.basurgan/Main/1. Works Files/2. Gits Works/Zenarth-Meta-Hackathon-2025/APP_Api/venv/lib/python3.14/site-packages/paramiko/transport.py", line 2363, in _check_banner
    buf = self.packetizer.readline(timeout)
  File "/Users/utkan.basurgan/Main/1. Works Files/2. Gits Works/Zenarth-Meta-Hackathon-2025/APP_Api/venv/lib/python3.14/site-packages/paramiko/packet.py", line 395, in readline
    buf += self._read_timeout(timeout)
           ~~~~~~~~~~~~~~~~~~^^^^^^^^^
  File "/Users/utkan.basurgan/Main/1. Works Files/2. Gits Works/Zenarth-Meta-Hackathon-2025/APP_Api/venv/lib/python3.14/site-packages/paramiko/packet.py", line 673, in _read_timeout
    raise socket.timeout()
TimeoutError

During handling of the above exception, another exception occurred:

Traceback (most recent call last):
  File "/Users/utkan.basurgan/Main/1. Works Files/2. Gits Works/Zenarth-Meta-Hackathon-2025/APP_Api/python_api.py", line 42, in connect_ssh
    client.connect(
    ~~~~~~~~~~~~~~^
        hostname=host,
        ^^^^^^^^^^^^^^
    ...<5 lines>...
        look_for_keys=False,
        ^^^^^^^^^^^^^^^^^^^^
    )
    ^
  File "/Users/utkan.basurgan/Main/1. Works Files/2. Gits Works/Zenarth-Meta-Hackathon-2025/APP_Api/venv/lib/python3.14/site-packages/paramiko/client.py", line 449, in connect
    t.start_client(timeout=timeout)
    ~~~~~~~~~~~~~~^^^^^^^^^^^^^^^^^
  File "/Users/utkan.basurgan/Main/1. Works Files/2. Gits Works/Zenarth-Meta-Hackathon-2025/APP_Api/venv/lib/python3.14/site-packages/paramiko/transport.py", line 768, in start_client
    raise e
  File "/Users/utkan.basurgan/Main/1. Works Files/2. Gits Works/Zenarth-Meta-Hackathon-2025/APP_Api/venv/lib/python3.14/site-packages/paramiko/transport.py", line 2179, in run
    self._check_banner()
    ~~~~~~~~~~~~~~~~~~^^
  File "/Users/utkan.basurgan/Main/1. Works Files/2. Gits Works/Zenarth-Meta-Hackathon-2025/APP_Api/venv/lib/python3.14/site-packages/paramiko/transport.py", line 2367, in _check_banner
    raise SSHException(
        "Error reading SSH protocol banner" + str(e)
    )
paramiko.ssh_exception.SSHException: Error reading SSH protocol banner

During handling of the above exception, another exception occurred:

Traceback (most recent call last):
  File "/Users/utkan.basurgan/Main/1. Works Files/2. Gits Works/Zenarth-Meta-Hackathon-2025/APP_Api/main_api.py", line 26, in <module>
    ssh = connect_ssh(HOST, PORT, USER, KEY_PATH, PASSFILE_PATH)
  File "/Users/utkan.basurgan/Main/1. Works Files/2. Gits Works/Zenarth-Meta-Hackathon-2025/APP_Api/python_api.py", line 52, in connect_ssh
    raise RuntimeError(f"SSH bağlantı hatası: {e}")
RuntimeError: SSH bağlantı hatası: Error reading SSH protocol banner

Return code: 1
Running main_api.py at 2025-10-25 23:33:55
Error: Exception (client): Error reading SSH protocol banner
Traceback (most recent call last):
  File "/Users/utkan.basurgan/Main/1. Works Files/2. Gits Works/Zenarth-Meta-Hackathon-2025/APP_Api/venv/lib/python3.14/site-packages/paramiko/transport.py", line 2363, in _check_banner
    buf = self.packetizer.readline(timeout)
  File "/Users/utkan.basurgan/Main/1. Works Files/2. Gits Works/Zenarth-Meta-Hackathon-2025/APP_Api/venv/lib/python3.14/site-packages/paramiko/packet.py", line 395, in readline
    buf += self._read_timeout(timeout)
           ~~~~~~~~~~~~~~~~~~^^^^^^^^^
  File "/Users/utkan.basurgan/Main/1. Works Files/2. Gits Works/Zenarth-Meta-Hackathon-2025/APP_Api/venv/lib/python3.14/site-packages/paramiko/packet.py", line 673, in _read_timeout
    raise socket.timeout()
TimeoutError

During handling of the above exception, another exception occurred:

Traceback (most recent call last):
  File "/Users/utkan.basurgan/Main/1. Works Files/2. Gits Works/Zenarth-Meta-Hackathon-2025/APP_Api/venv/lib/python3.14/site-packages/paramiko/transport.py", line 2179, in run
    self._check_banner()
    ~~~~~~~~~~~~~~~~~~^^
  File "/Users/utkan.basurgan/Main/1. Works Files/2. Gits Works/Zenarth-Meta-Hackathon-2025/APP_Api/venv/lib/python3.14/site-packages/paramiko/transport.py", line 2367, in _check_banner
    raise SSHException(
        "Error reading SSH protocol banner" + str(e)
    )
paramiko.ssh_exception.SSHException: Error reading SSH protocol banner

Traceback (most recent call last):
  File "/Users/utkan.basurgan/Main/1. Works Files/2. Gits Works/Zenarth-Meta-Hackathon-2025/APP_Api/venv/lib/python3.14/site-packages/paramiko/transport.py", line 2363, in _check_banner
    buf = self.packetizer.readline(timeout)
  File "/Users/utkan.basurgan/Main/1. Works Files/2. Gits Works/Zenarth-Meta-Hackathon-2025/APP_Api/venv/lib/python3.14/site-packages/paramiko/packet.py", line 395, in readline
    buf += self._read_timeout(timeout)
           ~~~~~~~~~~~~~~~~~~^^^^^^^^^
  File "/Users/utkan.basurgan/Main/1. Works Files/2. Gits Works/Zenarth-Meta-Hackathon-2025/APP_Api/venv/lib/python3.14/site-packages/paramiko/packet.py", line 673, in _read_timeout
    raise socket.timeout()
TimeoutError

During handling of the above exception, another exception occurred:

Traceback (most recent call last):
  File "/Users/utkan.basurgan/Main/1. Works Files/2. Gits Works/Zenarth-Meta-Hackathon-2025/APP_Api/python_api.py", line 42, in connect_ssh
    client.connect(
    ~~~~~~~~~~~~~~^
        hostname=host,
        ^^^^^^^^^^^^^^
    ...<5 lines>...
        look_for_keys=False,
        ^^^^^^^^^^^^^^^^^^^^
    )
    ^
  File "/Users/utkan.basurgan/Main/1. Works Files/2. Gits Works/Zenarth-Meta-Hackathon-2025/APP_Api/venv/lib/python3.14/site-packages/paramiko/client.py", line 449, in connect
    t.start_client(timeout=timeout)
    ~~~~~~~~~~~~~~^^^^^^^^^^^^^^^^^
  File "/Users/utkan.basurgan/Main/1. Works Files/2. Gits Works/Zenarth-Meta-Hackathon-2025/APP_Api/venv/lib/python3.14/site-packages/paramiko/transport.py", line 768, in start_client
    raise e
  File "/Users/utkan.basurgan/Main/1. Works Files/2. Gits Works/Zenarth-Meta-Hackathon-2025/APP_Api/venv/lib/python3.14/site-packages/paramiko/transport.py", line 2179, in run
    self._check_banner()
    ~~~~~~~~~~~~~~~~~~^^
  File "/Users/utkan.basurgan/Main/1. Works Files/2. Gits Works/Zenarth-Meta-Hackathon-2025/APP_Api/venv/lib/python3.14/site-packages/paramiko/transport.py", line 2367, in _check_banner
    raise SSHException(
        "Error reading SSH protocol banner" + str(e)
    )
paramiko.ssh_exception.SSHException: Error reading SSH protocol banner

During handling of the above exception, another exception occurred:

Traceback (most recent call last):
  File "/Users/utkan.basurgan/Main/1. Works Files/2. Gits Works/Zenarth-Meta-Hackathon-2025/APP_Api/main_api.py", line 26, in <module>
    ssh = connect_ssh(HOST, PORT, USER, KEY_PATH, PASSFILE_PATH)
  File "/Users/utkan.basurgan/Main/1. Works Files/2. Gits Works/Zenarth-Meta-Hackathon-2025/APP_Api/python_api.py", line 52, in connect_ssh
    raise RuntimeError(f"SSH bağlantı hatası: {e}")
RuntimeError: SSH bağlantı hatası: Error reading SSH protocol banner

Return code: 1
Running main_api.py at 2025-10-25 23:34:21
Error: Exception (client): Error reading SSH protocol banner
Traceback (most recent call last):
  File "/Users/utkan.basurgan/Main/1. Works Files/2. Gits Works/Zenarth-Meta-Hackathon-2025/APP_Api/venv/lib/python3.14/site-packages/paramiko/transport.py", line 2363, in _check_banner
    buf = self.packetizer.readline(timeout)
  File "/Users/utkan.basurgan/Main/1. Works Files/2. Gits Works/Zenarth-Meta-Hackathon-2025/APP_Api/venv/lib/python3.14/site-packages/paramiko/packet.py", line 395, in readline
    buf += self._read_timeout(timeout)
           ~~~~~~~~~~~~~~~~~~^^^^^^^^^
  File "/Users/utkan.basurgan/Main/1. Works Files/2. Gits Works/Zenarth-Meta-Hackathon-2025/APP_Api/venv/lib/python3.14/site-packages/paramiko/packet.py", line 673, in _read_timeout
    raise socket.timeout()
TimeoutError

During handling of the above exception, another exception occurred:

Traceback (most recent call last):
  File "/Users/utkan.basurgan/Main/1. Works Files/2. Gits Works/Zenarth-Meta-Hackathon-2025/APP_Api/venv/lib/python3.14/site-packages/paramiko/transport.py", line 2179, in run
    self._check_banner()
    ~~~~~~~~~~~~~~~~~~^^
  File "/Users/utkan.basurgan/Main/1. Works Files/2. Gits Works/Zenarth-Meta-Hackathon-2025/APP_Api/venv/lib/python3.14/site-packages/paramiko/transport.py", line 2367, in _check_banner
    raise SSHException(
        "Error reading SSH protocol banner" + str(e)
    )
paramiko.ssh_exception.SSHException: Error reading SSH protocol banner

Traceback (most recent call last):
  File "/Users/utkan.basurgan/Main/1. Works Files/2. Gits Works/Zenarth-Meta-Hackathon-2025/APP_Api/venv/lib/python3.14/site-packages/paramiko/transport.py", line 2363, in _check_banner
    buf = self.packetizer.readline(timeout)
  File "/Users/utkan.basurgan/Main/1. Works Files/2. Gits Works/Zenarth-Meta-Hackathon-2025/APP_Api/venv/lib/python3.14/site-packages/paramiko/packet.py", line 395, in readline
    buf += self._read_timeout(timeout)
           ~~~~~~~~~~~~~~~~~~^^^^^^^^^
  File "/Users/utkan.basurgan/Main/1. Works Files/2. Gits Works/Zenarth-Meta-Hackathon-2025/APP_Api/venv/lib/python3.14/site-packages/paramiko/packet.py", line 673, in _read_timeout
    raise socket.timeout()
TimeoutError

During handling of the above exception, another exception occurred:

Traceback (most recent call last):
  File "/Users/utkan.basurgan/Main/1. Works Files/2. Gits Works/Zenarth-Meta-Hackathon-2025/APP_Api/python_api.py", line 42, in connect_ssh
    client.connect(
    ~~~~~~~~~~~~~~^
        hostname=host,
        ^^^^^^^^^^^^^^
    ...<5 lines>...
        look_for_keys=False,
        ^^^^^^^^^^^^^^^^^^^^
    )
    ^
  File "/Users/utkan.basurgan/Main/1. Works Files/2. Gits Works/Zenarth-Meta-Hackathon-2025/APP_Api/venv/lib/python3.14/site-packages/paramiko/client.py", line 449, in connect
    t.start_client(timeout=timeout)
    ~~~~~~~~~~~~~~^^^^^^^^^^^^^^^^^
  File "/Users/utkan.basurgan/Main/1. Works Files/2. Gits Works/Zenarth-Meta-Hackathon-2025/APP_Api/venv/lib/python3.14/site-packages/paramiko/transport.py", line 768, in start_client
    raise e
  File "/Users/utkan.basurgan/Main/1. Works Files/2. Gits Works/Zenarth-Meta-Hackathon-2025/APP_Api/venv/lib/python3.14/site-packages/paramiko/transport.py", line 2179, in run
    self._check_banner()
    ~~~~~~~~~~~~~~~~~~^^
  File "/Users/utkan.basurgan/Main/1. Works Files/2. Gits Works/Zenarth-Meta-Hackathon-2025/APP_Api/venv/lib/python3.14/site-packages/paramiko/transport.py", line 2367, in _check_banner
    raise SSHException(
        "Error reading SSH protocol banner" + str(e)
    )
paramiko.ssh_exception.SSHException: Error reading SSH protocol banner

During handling of the above exception, another exception occurred:

Traceback (most recent call last):
  File "/Users/utkan.basurgan/Main/1. Works Files/2. Gits Works/Zenarth-Meta-Hackathon-2025/APP_Api/main_api.py", line 26, in <module>
    ssh = connect_ssh(HOST, PORT, USER, KEY_PATH, PASSFILE_PATH)
  File "/Users/utkan.basurgan/Main/1. Works Files/2. Gits Works/Zenarth-Meta-Hackathon-2025/APP_Api/python_api.py", line 52, in connect_ssh
    raise RuntimeError(f"SSH bağlantı hatası: {e}")
RuntimeError: SSH bağlantı hatası: Error reading SSH protocol banner

Return code: 1
Running main_api.py at 2025-10-25 23:34:48
Error: Exception (client): Error reading SSH protocol banner
Traceback (most recent call last):
  File "/Users/utkan.basurgan/Main/1. Works Files/2. Gits Works/Zenarth-Meta-Hackathon-2025/APP_Api/venv/lib/python3.14/site-packages/paramiko/transport.py", line 2363, in _check_banner
    buf = self.packetizer.readline(timeout)
  File "/Users/utkan.basurgan/Main/1. Works Files/2. Gits Works/Zenarth-Meta-Hackathon-2025/APP_Api/venv/lib/python3.14/site-packages/paramiko/packet.py", line 395, in readline
    buf += self._read_timeout(timeout)
           ~~~~~~~~~~~~~~~~~~^^^^^^^^^
  File "/Users/utkan.basurgan/Main/1. Works Files/2. Gits Works/Zenarth-Meta-Hackathon-2025/APP_Api/venv/lib/python3.14/site-packages/paramiko/packet.py", line 673, in _read_timeout
    raise socket.timeout()
TimeoutError

During handling of the above exception, another exception occurred:

Traceback (most recent call last):
  File "/Users/utkan.basurgan/Main/1. Works Files/2. Gits Works/Zenarth-Meta-Hackathon-2025/APP_Api/venv/lib/python3.14/site-packages/paramiko/transport.py", line 2179, in run
    self._check_banner()
    ~~~~~~~~~~~~~~~~~~^^
  File "/Users/utkan.basurgan/Main/1. Works Files/2. Gits Works/Zenarth-Meta-Hackathon-2025/APP_Api/venv/lib/python3.14/site-packages/paramiko/transport.py", line 2367, in _check_banner
    raise SSHException(
        "Error reading SSH protocol banner" + str(e)
    )
paramiko.ssh_exception.SSHException: Error reading SSH protocol banner

Traceback (most recent call last):
  File "/Users/utkan.basurgan/Main/1. Works Files/2. Gits Works/Zenarth-Meta-Hackathon-2025/APP_Api/venv/lib/python3.14/site-packages/paramiko/transport.py", line 2363, in _check_banner
    buf = self.packetizer.readline(timeout)
  File "/Users/utkan.basurgan/Main/1. Works Files/2. Gits Works/Zenarth-Meta-Hackathon-2025/APP_Api/venv/lib/python3.14/site-packages/paramiko/packet.py", line 395, in readline
    buf += self._read_timeout(timeout)
           ~~~~~~~~~~~~~~~~~~^^^^^^^^^
  File "/Users/utkan.basurgan/Main/1. Works Files/2. Gits Works/Zenarth-Meta-Hackathon-2025/APP_Api/venv/lib/python3.14/site-packages/paramiko/packet.py", line 673, in _read_timeout
    raise socket.timeout()
TimeoutError

During handling of the above exception, another exception occurred:

Traceback (most recent call last):
  File "/Users/utkan.basurgan/Main/1. Works Files/2. Gits Works/Zenarth-Meta-Hackathon-2025/APP_Api/python_api.py", line 42, in connect_ssh
    client.connect(
    ~~~~~~~~~~~~~~^
        hostname=host,
        ^^^^^^^^^^^^^^
    ...<5 lines>...
        look_for_keys=False,
        ^^^^^^^^^^^^^^^^^^^^
    )
    ^
  File "/Users/utkan.basurgan/Main/1. Works Files/2. Gits Works/Zenarth-Meta-Hackathon-2025/APP_Api/venv/lib/python3.14/site-packages/paramiko/client.py", line 449, in connect
    t.start_client(timeout=timeout)
    ~~~~~~~~~~~~~~^^^^^^^^^^^^^^^^^
  File "/Users/utkan.basurgan/Main/1. Works Files/2. Gits Works/Zenarth-Meta-Hackathon-2025/APP_Api/venv/lib/python3.14/site-packages/paramiko/transport.py", line 768, in start_client
    raise e
  File "/Users/utkan.basurgan/Main/1. Works Files/2. Gits Works/Zenarth-Meta-Hackathon-2025/APP_Api/venv/lib/python3.14/site-packages/paramiko/transport.py", line 2179, in run
    self._check_banner()
    ~~~~~~~~~~~~~~~~~~^^
  File "/Users/utkan.basurgan/Main/1. Works Files/2. Gits Works/Zenarth-Meta-Hackathon-2025/APP_Api/venv/lib/python3.14/site-packages/paramiko/transport.py", line 2367, in _check_banner
    raise SSHException(
        "Error reading SSH protocol banner" + str(e)
    )
paramiko.ssh_exception.SSHException: Error reading SSH protocol banner

During handling of the above exception, another exception occurred:

Traceback (most recent call last):
  File "/Users/utkan.basurgan/Main/1. Works Files/2. Gits Works/Zenarth-Meta-Hackathon-2025/APP_Api/main_api.py", line 26, in <module>
    ssh = connect_ssh(HOST, PORT, USER, KEY_PATH, PASSFILE_PATH)
  File "/Users/utkan.basurgan/Main/1. Works Files/2. Gits Works/Zenarth-Meta-Hackathon-2025/APP_Api/python_api.py", line 52, in connect_ssh
    raise RuntimeError(f"SSH bağlantı hatası: {e}")
RuntimeError: SSH bağlantı hatası: Error reading SSH protocol banner

Return code: 1
Running main_api.py at 2025-10-25 23:35:14
Error: Exception (client): Error reading SSH protocol banner
Traceback (most recent call last):
  File "/Users/utkan.basurgan/Main/1. Works Files/2. Gits Works/Zenarth-Meta-Hackathon-2025/APP_Api/venv/lib/python3.14/site-packages/paramiko/transport.py", line 2363, in _check_banner
    buf = self.packetizer.readline(timeout)
  File "/Users/utkan.basurgan/Main/1. Works Files/2. Gits Works/Zenarth-Meta-Hackathon-2025/APP_Api/venv/lib/python3.14/site-packages/paramiko/packet.py", line 395, in readline
    buf += self._read_timeout(timeout)
           ~~~~~~~~~~~~~~~~~~^^^^^^^^^
  File "/Users/utkan.basurgan/Main/1. Works Files/2. Gits Works/Zenarth-Meta-Hackathon-2025/APP_Api/venv/lib/python3.14/site-packages/paramiko/packet.py", line 673, in _read_timeout
    raise socket.timeout()
TimeoutError

During handling of the above exception, another exception occurred:

Traceback (most recent call last):
  File "/Users/utkan.basurgan/Main/1. Works Files/2. Gits Works/Zenarth-Meta-Hackathon-2025/APP_Api/venv/lib/python3.14/site-packages/paramiko/transport.py", line 2179, in run
    self._check_banner()
    ~~~~~~~~~~~~~~~~~~^^
  File "/Users/utkan.basurgan/Main/1. Works Files/2. Gits Works/Zenarth-Meta-Hackathon-2025/APP_Api/venv/lib/python3.14/site-packages/paramiko/transport.py", line 2367, in _check_banner
    raise SSHException(
        "Error reading SSH protocol banner" + str(e)
    )
paramiko.ssh_exception.SSHException: Error reading SSH protocol banner

Traceback (most recent call last):
  File "/Users/utkan.basurgan/Main/1. Works Files/2. Gits Works/Zenarth-Meta-Hackathon-2025/APP_Api/venv/lib/python3.14/site-packages/paramiko/transport.py", line 2363, in _check_banner
    buf = self.packetizer.readline(timeout)
  File "/Users/utkan.basurgan/Main/1. Works Files/2. Gits Works/Zenarth-Meta-Hackathon-2025/APP_Api/venv/lib/python3.14/site-packages/paramiko/packet.py", line 395, in readline
    buf += self._read_timeout(timeout)
           ~~~~~~~~~~~~~~~~~~^^^^^^^^^
  File "/Users/utkan.basurgan/Main/1. Works Files/2. Gits Works/Zenarth-Meta-Hackathon-2025/APP_Api/venv/lib/python3.14/site-packages/paramiko/packet.py", line 673, in _read_timeout
    raise socket.timeout()
TimeoutError

During handling of the above exception, another exception occurred:

Traceback (most recent call last):
  File "/Users/utkan.basurgan/Main/1. Works Files/2. Gits Works/Zenarth-Meta-Hackathon-2025/APP_Api/python_api.py", line 42, in connect_ssh
    client.connect(
    ~~~~~~~~~~~~~~^
        hostname=host,
        ^^^^^^^^^^^^^^
    ...<5 lines>...
        look_for_keys=False,
        ^^^^^^^^^^^^^^^^^^^^
    )
    ^
  File "/Users/utkan.basurgan/Main/1. Works Files/2. Gits Works/Zenarth-Meta-Hackathon-2025/APP_Api/venv/lib/python3.14/site-packages/paramiko/client.py", line 449, in connect
    t.start_client(timeout=timeout)
    ~~~~~~~~~~~~~~^^^^^^^^^^^^^^^^^
  File "/Users/utkan.basurgan/Main/1. Works Files/2. Gits Works/Zenarth-Meta-Hackathon-2025/APP_Api/venv/lib/python3.14/site-packages/paramiko/transport.py", line 768, in start_client
    raise e
  File "/Users/utkan.basurgan/Main/1. Works Files/2. Gits Works/Zenarth-Meta-Hackathon-2025/APP_Api/venv/lib/python3.14/site-packages/paramiko/transport.py", line 2179, in run
    self._check_banner()
    ~~~~~~~~~~~~~~~~~~^^
  File "/Users/utkan.basurgan/Main/1. Works Files/2. Gits Works/Zenarth-Meta-Hackathon-2025/APP_Api/venv/lib/python3.14/site-packages/paramiko/transport.py", line 2367, in _check_banner
    raise SSHException(
        "Error reading SSH protocol banner" + str(e)
    )
paramiko.ssh_exception.SSHException: Error reading SSH protocol banner

During handling of the above exception, another exception occurred:

Traceback (most recent call last):
  File "/Users/utkan.basurgan/Main/1. Works Files/2. Gits Works/Zenarth-Meta-Hackathon-2025/APP_Api/main_api.py", line 26, in <module>
    ssh = connect_ssh(HOST, PORT, USER, KEY_PATH, PASSFILE_PATH)
  File "/Users/utkan.basurgan/Main/1. Works Files/2. Gits Works/Zenarth-Meta-Hackathon-2025/APP_Api/python_api.py", line 52, in connect_ssh
    raise RuntimeError(f"SSH bağlantı hatası: {e}")
RuntimeError: SSH bağlantı hatası: Error reading SSH protocol banner

Return code: 1
Running main_api.py at 2025-10-25 23:35:41
Error: Exception (client): Error reading SSH protocol banner
Traceback (most recent call last):
  File "/Users/utkan.basurgan/Main/1. Works Files/2. Gits Works/Zenarth-Meta-Hackathon-2025/APP_Api/venv/lib/python3.14/site-packages/paramiko/transport.py", line 2363, in _check_banner
    buf = self.packetizer.readline(timeout)
  File "/Users/utkan.basurgan/Main/1. Works Files/2. Gits Works/Zenarth-Meta-Hackathon-2025/APP_Api/venv/lib/python3.14/site-packages/paramiko/packet.py", line 395, in readline
    buf += self._read_timeout(timeout)
           ~~~~~~~~~~~~~~~~~~^^^^^^^^^
  File "/Users/utkan.basurgan/Main/1. Works Files/2. Gits Works/Zenarth-Meta-Hackathon-2025/APP_Api/venv/lib/python3.14/site-packages/paramiko/packet.py", line 673, in _read_timeout
    raise socket.timeout()
TimeoutError

During handling of the above exception, another exception occurred:

Traceback (most recent call last):
  File "/Users/utkan.basurgan/Main/1. Works Files/2. Gits Works/Zenarth-Meta-Hackathon-2025/APP_Api/venv/lib/python3.14/site-packages/paramiko/transport.py", line 2179, in run
    self._check_banner()
    ~~~~~~~~~~~~~~~~~~^^
  File "/Users/utkan.basurgan/Main/1. Works Files/2. Gits Works/Zenarth-Meta-Hackathon-2025/APP_Api/venv/lib/python3.14/site-packages/paramiko/transport.py", line 2367, in _check_banner
    raise SSHException(
        "Error reading SSH protocol banner" + str(e)
    )
paramiko.ssh_exception.SSHException: Error reading SSH protocol banner

Traceback (most recent call last):
  File "/Users/utkan.basurgan/Main/1. Works Files/2. Gits Works/Zenarth-Meta-Hackathon-2025/APP_Api/venv/lib/python3.14/site-packages/paramiko/transport.py", line 2363, in _check_banner
    buf = self.packetizer.readline(timeout)
  File "/Users/utkan.basurgan/Main/1. Works Files/2. Gits Works/Zenarth-Meta-Hackathon-2025/APP_Api/venv/lib/python3.14/site-packages/paramiko/packet.py", line 395, in readline
    buf += self._read_timeout(timeout)
           ~~~~~~~~~~~~~~~~~~^^^^^^^^^
  File "/Users/utkan.basurgan/Main/1. Works Files/2. Gits Works/Zenarth-Meta-Hackathon-2025/APP_Api/venv/lib/python3.14/site-packages/paramiko/packet.py", line 673, in _read_timeout
    raise socket.timeout()
TimeoutError

During handling of the above exception, another exception occurred:

Traceback (most recent call last):
  File "/Users/utkan.basurgan/Main/1. Works Files/2. Gits Works/Zenarth-Meta-Hackathon-2025/APP_Api/python_api.py", line 42, in connect_ssh
    client.connect(
    ~~~~~~~~~~~~~~^
        hostname=host,
        ^^^^^^^^^^^^^^
    ...<5 lines>...
        look_for_keys=False,
        ^^^^^^^^^^^^^^^^^^^^
    )
    ^
  File "/Users/utkan.basurgan/Main/1. Works Files/2. Gits Works/Zenarth-Meta-Hackathon-2025/APP_Api/venv/lib/python3.14/site-packages/paramiko/client.py", line 449, in connect
    t.start_client(timeout=timeout)
    ~~~~~~~~~~~~~~^^^^^^^^^^^^^^^^^
  File "/Users/utkan.basurgan/Main/1. Works Files/2. Gits Works/Zenarth-Meta-Hackathon-2025/APP_Api/venv/lib/python3.14/site-packages/paramiko/transport.py", line 768, in start_client
    raise e
  File "/Users/utkan.basurgan/Main/1. Works Files/2. Gits Works/Zenarth-Meta-Hackathon-2025/APP_Api/venv/lib/python3.14/site-packages/paramiko/transport.py", line 2179, in run
    self._check_banner()
    ~~~~~~~~~~~~~~~~~~^^
  File "/Users/utkan.basurgan/Main/1. Works Files/2. Gits Works/Zenarth-Meta-Hackathon-2025/APP_Api/venv/lib/python3.14/site-packages/paramiko/transport.py", line 2367, in _check_banner
    raise SSHException(
        "Error reading SSH protocol banner" + str(e)
    )
paramiko.ssh_exception.SSHException: Error reading SSH protocol banner

During handling of the above exception, another exception occurred:

Traceback (most recent call last):
  File "/Users/utkan.basurgan/Main/1. Works Files/2. Gits Works/Zenarth-Meta-Hackathon-2025/APP_Api/main_api.py", line 26, in <module>
    ssh = connect_ssh(HOST, PORT, USER, KEY_PATH, PASSFILE_PATH)
  File "/Users/utkan.basurgan/Main/1. Works Files/2. Gits Works/Zenarth-Meta-Hackathon-2025/APP_Api/python_api.py", line 52, in connect_ssh
    raise RuntimeError(f"SSH bağlantı hatası: {e}")
RuntimeError: SSH bağlantı hatası: Error reading SSH protocol banner

Return code: 1
Running main_api.py at 2025-10-25 23:36:07
Error: Exception (client): Error reading SSH protocol banner
Traceback (most recent call last):
  File "/Users/utkan.basurgan/Main/1. Works Files/2. Gits Works/Zenarth-Meta-Hackathon-2025/APP_Api/venv/lib/python3.14/site-packages/paramiko/transport.py", line 2363, in _check_banner
    buf = self.packetizer.readline(timeout)
  File "/Users/utkan.basurgan/Main/1. Works Files/2. Gits Works/Zenarth-Meta-Hackathon-2025/APP_Api/venv/lib/python3.14/site-packages/paramiko/packet.py", line 395, in readline
    buf += self._read_timeout(timeout)
           ~~~~~~~~~~~~~~~~~~^^^^^^^^^
  File "/Users/utkan.basurgan/Main/1. Works Files/2. Gits Works/Zenarth-Meta-Hackathon-2025/APP_Api/venv/lib/python3.14/site-packages/paramiko/packet.py", line 673, in _read_timeout
    raise socket.timeout()
TimeoutError

During handling of the above exception, another exception occurred:

Traceback (most recent call last):
  File "/Users/utkan.basurgan/Main/1. Works Files/2. Gits Works/Zenarth-Meta-Hackathon-2025/APP_Api/venv/lib/python3.14/site-packages/paramiko/transport.py", line 2179, in run
    self._check_banner()
    ~~~~~~~~~~~~~~~~~~^^
  File "/Users/utkan.basurgan/Main/1. Works Files/2. Gits Works/Zenarth-Meta-Hackathon-2025/APP_Api/venv/lib/python3.14/site-packages/paramiko/transport.py", line 2367, in _check_banner
    raise SSHException(
        "Error reading SSH protocol banner" + str(e)
    )
paramiko.ssh_exception.SSHException: Error reading SSH protocol banner

Traceback (most recent call last):
  File "/Users/utkan.basurgan/Main/1. Works Files/2. Gits Works/Zenarth-Meta-Hackathon-2025/APP_Api/venv/lib/python3.14/site-packages/paramiko/transport.py", line 2363, in _check_banner
    buf = self.packetizer.readline(timeout)
  File "/Users/utkan.basurgan/Main/1. Works Files/2. Gits Works/Zenarth-Meta-Hackathon-2025/APP_Api/venv/lib/python3.14/site-packages/paramiko/packet.py", line 395, in readline
    buf += self._read_timeout(timeout)
           ~~~~~~~~~~~~~~~~~~^^^^^^^^^
  File "/Users/utkan.basurgan/Main/1. Works Files/2. Gits Works/Zenarth-Meta-Hackathon-2025/APP_Api/venv/lib/python3.14/site-packages/paramiko/packet.py", line 673, in _read_timeout
    raise socket.timeout()
TimeoutError

During handling of the above exception, another exception occurred:

Traceback (most recent call last):
  File "/Users/utkan.basurgan/Main/1. Works Files/2. Gits Works/Zenarth-Meta-Hackathon-2025/APP_Api/python_api.py", line 42, in connect_ssh
    client.connect(
    ~~~~~~~~~~~~~~^
        hostname=host,
        ^^^^^^^^^^^^^^
    ...<5 lines>...
        look_for_keys=False,
        ^^^^^^^^^^^^^^^^^^^^
    )
    ^
  File "/Users/utkan.basurgan/Main/1. Works Files/2. Gits Works/Zenarth-Meta-Hackathon-2025/APP_Api/venv/lib/python3.14/site-packages/paramiko/client.py", line 449, in connect
    t.start_client(timeout=timeout)
    ~~~~~~~~~~~~~~^^^^^^^^^^^^^^^^^
  File "/Users/utkan.basurgan/Main/1. Works Files/2. Gits Works/Zenarth-Meta-Hackathon-2025/APP_Api/venv/lib/python3.14/site-packages/paramiko/transport.py", line 768, in start_client
    raise e
  File "/Users/utkan.basurgan/Main/1. Works Files/2. Gits Works/Zenarth-Meta-Hackathon-2025/APP_Api/venv/lib/python3.14/site-packages/paramiko/transport.py", line 2179, in run
    self._check_banner()
    ~~~~~~~~~~~~~~~~~~^^
  File "/Users/utkan.basurgan/Main/1. Works Files/2. Gits Works/Zenarth-Meta-Hackathon-2025/APP_Api/venv/lib/python3.14/site-packages/paramiko/transport.py", line 2367, in _check_banner
    raise SSHException(
        "Error reading SSH protocol banner" + str(e)
    )
paramiko.ssh_exception.SSHException: Error reading SSH protocol banner

During handling of the above exception, another exception occurred:

Traceback (most recent call last):
  File "/Users/utkan.basurgan/Main/1. Works Files/2. Gits Works/Zenarth-Meta-Hackathon-2025/APP_Api/main_api.py", line 26, in <module>
    ssh = connect_ssh(HOST, PORT, USER, KEY_PATH, PASSFILE_PATH)
  File "/Users/utkan.basurgan/Main/1. Works Files/2. Gits Works/Zenarth-Meta-Hackathon-2025/APP_Api/python_api.py", line 52, in connect_ssh
    raise RuntimeError(f"SSH bağlantı hatası: {e}")
RuntimeError: SSH bağlantı hatası: Error reading SSH protocol banner

Return code: 1
Running main_api.py at 2025-10-25 23:36:33
Error: Exception (client): Error reading SSH protocol banner
Traceback (most recent call last):
  File "/Users/utkan.basurgan/Main/1. Works Files/2. Gits Works/Zenarth-Meta-Hackathon-2025/APP_Api/venv/lib/python3.14/site-packages/paramiko/transport.py", line 2363, in _check_banner
    buf = self.packetizer.readline(timeout)
  File "/Users/utkan.basurgan/Main/1. Works Files/2. Gits Works/Zenarth-Meta-Hackathon-2025/APP_Api/venv/lib/python3.14/site-packages/paramiko/packet.py", line 395, in readline
    buf += self._read_timeout(timeout)
           ~~~~~~~~~~~~~~~~~~^^^^^^^^^
  File "/Users/utkan.basurgan/Main/1. Works Files/2. Gits Works/Zenarth-Meta-Hackathon-2025/APP_Api/venv/lib/python3.14/site-packages/paramiko/packet.py", line 673, in _read_timeout
    raise socket.timeout()
TimeoutError

During handling of the above exception, another exception occurred:

Traceback (most recent call last):
  File "/Users/utkan.basurgan/Main/1. Works Files/2. Gits Works/Zenarth-Meta-Hackathon-2025/APP_Api/venv/lib/python3.14/site-packages/paramiko/transport.py", line 2179, in run
    self._check_banner()
    ~~~~~~~~~~~~~~~~~~^^
  File "/Users/utkan.basurgan/Main/1. Works Files/2. Gits Works/Zenarth-Meta-Hackathon-2025/APP_Api/venv/lib/python3.14/site-packages/paramiko/transport.py", line 2367, in _check_banner
    raise SSHException(
        "Error reading SSH protocol banner" + str(e)
    )
paramiko.ssh_exception.SSHException: Error reading SSH protocol banner

Traceback (most recent call last):
  File "/Users/utkan.basurgan/Main/1. Works Files/2. Gits Works/Zenarth-Meta-Hackathon-2025/APP_Api/venv/lib/python3.14/site-packages/paramiko/transport.py", line 2363, in _check_banner
    buf = self.packetizer.readline(timeout)
  File "/Users/utkan.basurgan/Main/1. Works Files/2. Gits Works/Zenarth-Meta-Hackathon-2025/APP_Api/venv/lib/python3.14/site-packages/paramiko/packet.py", line 395, in readline
    buf += self._read_timeout(timeout)
           ~~~~~~~~~~~~~~~~~~^^^^^^^^^
  File "/Users/utkan.basurgan/Main/1. Works Files/2. Gits Works/Zenarth-Meta-Hackathon-2025/APP_Api/venv/lib/python3.14/site-packages/paramiko/packet.py", line 673, in _read_timeout
    raise socket.timeout()
TimeoutError

During handling of the above exception, another exception occurred:

Traceback (most recent call last):
  File "/Users/utkan.basurgan/Main/1. Works Files/2. Gits Works/Zenarth-Meta-Hackathon-2025/APP_Api/python_api.py", line 42, in connect_ssh
    client.connect(
    ~~~~~~~~~~~~~~^
        hostname=host,
        ^^^^^^^^^^^^^^
    ...<5 lines>...
        look_for_keys=False,
        ^^^^^^^^^^^^^^^^^^^^
    )
    ^
  File "/Users/utkan.basurgan/Main/1. Works Files/2. Gits Works/Zenarth-Meta-Hackathon-2025/APP_Api/venv/lib/python3.14/site-packages/paramiko/client.py", line 449, in connect
    t.start_client(timeout=timeout)
    ~~~~~~~~~~~~~~^^^^^^^^^^^^^^^^^
  File "/Users/utkan.basurgan/Main/1. Works Files/2. Gits Works/Zenarth-Meta-Hackathon-2025/APP_Api/venv/lib/python3.14/site-packages/paramiko/transport.py", line 768, in start_client
    raise e
  File "/Users/utkan.basurgan/Main/1. Works Files/2. Gits Works/Zenarth-Meta-Hackathon-2025/APP_Api/venv/lib/python3.14/site-packages/paramiko/transport.py", line 2179, in run
    self._check_banner()
    ~~~~~~~~~~~~~~~~~~^^
  File "/Users/utkan.basurgan/Main/1. Works Files/2. Gits Works/Zenarth-Meta-Hackathon-2025/APP_Api/venv/lib/python3.14/site-packages/paramiko/transport.py", line 2367, in _check_banner
    raise SSHException(
        "Error reading SSH protocol banner" + str(e)
    )
paramiko.ssh_exception.SSHException: Error reading SSH protocol banner

During handling of the above exception, another exception occurred:

Traceback (most recent call last):
  File "/Users/utkan.basurgan/Main/1. Works Files/2. Gits Works/Zenarth-Meta-Hackathon-2025/APP_Api/main_api.py", line 26, in <module>
    ssh = connect_ssh(HOST, PORT, USER, KEY_PATH, PASSFILE_PATH)
  File "/Users/utkan.basurgan/Main/1. Works Files/2. Gits Works/Zenarth-Meta-Hackathon-2025/APP_Api/python_api.py", line 52, in connect_ssh
    raise RuntimeError(f"SSH bağlantı hatası: {e}")
RuntimeError: SSH bağlantı hatası: Error reading SSH protocol banner

Return code: 1
Running main_api.py at 2025-10-25 23:36:59
Error: Exception (client): Error reading SSH protocol banner
Traceback (most recent call last):
  File "/Users/utkan.basurgan/Main/1. Works Files/2. Gits Works/Zenarth-Meta-Hackathon-2025/APP_Api/venv/lib/python3.14/site-packages/paramiko/transport.py", line 2363, in _check_banner
    buf = self.packetizer.readline(timeout)
  File "/Users/utkan.basurgan/Main/1. Works Files/2. Gits Works/Zenarth-Meta-Hackathon-2025/APP_Api/venv/lib/python3.14/site-packages/paramiko/packet.py", line 395, in readline
    buf += self._read_timeout(timeout)
           ~~~~~~~~~~~~~~~~~~^^^^^^^^^
  File "/Users/utkan.basurgan/Main/1. Works Files/2. Gits Works/Zenarth-Meta-Hackathon-2025/APP_Api/venv/lib/python3.14/site-packages/paramiko/packet.py", line 673, in _read_timeout
    raise socket.timeout()
TimeoutError

During handling of the above exception, another exception occurred:

Traceback (most recent call last):
  File "/Users/utkan.basurgan/Main/1. Works Files/2. Gits Works/Zenarth-Meta-Hackathon-2025/APP_Api/venv/lib/python3.14/site-packages/paramiko/transport.py", line 2179, in run
    self._check_banner()
    ~~~~~~~~~~~~~~~~~~^^
  File "/Users/utkan.basurgan/Main/1. Works Files/2. Gits Works/Zenarth-Meta-Hackathon-2025/APP_Api/venv/lib/python3.14/site-packages/paramiko/transport.py", line 2367, in _check_banner
    raise SSHException(
        "Error reading SSH protocol banner" + str(e)
    )
paramiko.ssh_exception.SSHException: Error reading SSH protocol banner

Traceback (most recent call last):
  File "/Users/utkan.basurgan/Main/1. Works Files/2. Gits Works/Zenarth-Meta-Hackathon-2025/APP_Api/venv/lib/python3.14/site-packages/paramiko/transport.py", line 2363, in _check_banner
    buf = self.packetizer.readline(timeout)
  File "/Users/utkan.basurgan/Main/1. Works Files/2. Gits Works/Zenarth-Meta-Hackathon-2025/APP_Api/venv/lib/python3.14/site-packages/paramiko/packet.py", line 395, in readline
    buf += self._read_timeout(timeout)
           ~~~~~~~~~~~~~~~~~~^^^^^^^^^
  File "/Users/utkan.basurgan/Main/1. Works Files/2. Gits Works/Zenarth-Meta-Hackathon-2025/APP_Api/venv/lib/python3.14/site-packages/paramiko/packet.py", line 673, in _read_timeout
    raise socket.timeout()
TimeoutError

During handling of the above exception, another exception occurred:

Traceback (most recent call last):
  File "/Users/utkan.basurgan/Main/1. Works Files/2. Gits Works/Zenarth-Meta-Hackathon-2025/APP_Api/python_api.py", line 42, in connect_ssh
    client.connect(
    ~~~~~~~~~~~~~~^
        hostname=host,
        ^^^^^^^^^^^^^^
    ...<5 lines>...
        look_for_keys=False,
        ^^^^^^^^^^^^^^^^^^^^
    )
    ^
  File "/Users/utkan.basurgan/Main/1. Works Files/2. Gits Works/Zenarth-Meta-Hackathon-2025/APP_Api/venv/lib/python3.14/site-packages/paramiko/client.py", line 449, in connect
    t.start_client(timeout=timeout)
    ~~~~~~~~~~~~~~^^^^^^^^^^^^^^^^^
  File "/Users/utkan.basurgan/Main/1. Works Files/2. Gits Works/Zenarth-Meta-Hackathon-2025/APP_Api/venv/lib/python3.14/site-packages/paramiko/transport.py", line 768, in start_client
    raise e
  File "/Users/utkan.basurgan/Main/1. Works Files/2. Gits Works/Zenarth-Meta-Hackathon-2025/APP_Api/venv/lib/python3.14/site-packages/paramiko/transport.py", line 2179, in run
    self._check_banner()
    ~~~~~~~~~~~~~~~~~~^^
  File "/Users/utkan.basurgan/Main/1. Works Files/2. Gits Works/Zenarth-Meta-Hackathon-2025/APP_Api/venv/lib/python3.14/site-packages/paramiko/transport.py", line 2367, in _check_banner
    raise SSHException(
        "Error reading SSH protocol banner" + str(e)
    )
paramiko.ssh_exception.SSHException: Error reading SSH protocol banner

During handling of the above exception, another exception occurred:

Traceback (most recent call last):
  File "/Users/utkan.basurgan/Main/1. Works Files/2. Gits Works/Zenarth-Meta-Hackathon-2025/APP_Api/main_api.py", line 26, in <module>
    ssh = connect_ssh(HOST, PORT, USER, KEY_PATH, PASSFILE_PATH)
  File "/Users/utkan.basurgan/Main/1. Works Files/2. Gits Works/Zenarth-Meta-Hackathon-2025/APP_Api/python_api.py", line 52, in connect_ssh
    raise RuntimeError(f"SSH bağlantı hatası: {e}")
RuntimeError: SSH bağlantı hatası: Error reading SSH protocol banner

Return code: 1
Running main_api.py at 2025-10-25 23:37:25
Error: Exception (client): Error reading SSH protocol banner
Traceback (most recent call last):
  File "/Users/utkan.basurgan/Main/1. Works Files/2. Gits Works/Zenarth-Meta-Hackathon-2025/APP_Api/venv/lib/python3.14/site-packages/paramiko/transport.py", line 2363, in _check_banner
    buf = self.packetizer.readline(timeout)
  File "/Users/utkan.basurgan/Main/1. Works Files/2. Gits Works/Zenarth-Meta-Hackathon-2025/APP_Api/venv/lib/python3.14/site-packages/paramiko/packet.py", line 395, in readline
    buf += self._read_timeout(timeout)
           ~~~~~~~~~~~~~~~~~~^^^^^^^^^
  File "/Users/utkan.basurgan/Main/1. Works Files/2. Gits Works/Zenarth-Meta-Hackathon-2025/APP_Api/venv/lib/python3.14/site-packages/paramiko/packet.py", line 673, in _read_timeout
    raise socket.timeout()
TimeoutError

During handling of the above exception, another exception occurred:

Traceback (most recent call last):
  File "/Users/utkan.basurgan/Main/1. Works Files/2. Gits Works/Zenarth-Meta-Hackathon-2025/APP_Api/venv/lib/python3.14/site-packages/paramiko/transport.py", line 2179, in run
    self._check_banner()
    ~~~~~~~~~~~~~~~~~~^^
  File "/Users/utkan.basurgan/Main/1. Works Files/2. Gits Works/Zenarth-Meta-Hackathon-2025/APP_Api/venv/lib/python3.14/site-packages/paramiko/transport.py", line 2367, in _check_banner
    raise SSHException(
        "Error reading SSH protocol banner" + str(e)
    )
paramiko.ssh_exception.SSHException: Error reading SSH protocol banner

Traceback (most recent call last):
  File "/Users/utkan.basurgan/Main/1. Works Files/2. Gits Works/Zenarth-Meta-Hackathon-2025/APP_Api/venv/lib/python3.14/site-packages/paramiko/transport.py", line 2363, in _check_banner
    buf = self.packetizer.readline(timeout)
  File "/Users/utkan.basurgan/Main/1. Works Files/2. Gits Works/Zenarth-Meta-Hackathon-2025/APP_Api/venv/lib/python3.14/site-packages/paramiko/packet.py", line 395, in readline
    buf += self._read_timeout(timeout)
           ~~~~~~~~~~~~~~~~~~^^^^^^^^^
  File "/Users/utkan.basurgan/Main/1. Works Files/2. Gits Works/Zenarth-Meta-Hackathon-2025/APP_Api/venv/lib/python3.14/site-packages/paramiko/packet.py", line 673, in _read_timeout
    raise socket.timeout()
TimeoutError

During handling of the above exception, another exception occurred:

Traceback (most recent call last):
  File "/Users/utkan.basurgan/Main/1. Works Files/2. Gits Works/Zenarth-Meta-Hackathon-2025/APP_Api/python_api.py", line 42, in connect_ssh
    client.connect(
    ~~~~~~~~~~~~~~^
        hostname=host,
        ^^^^^^^^^^^^^^
    ...<5 lines>...
        look_for_keys=False,
        ^^^^^^^^^^^^^^^^^^^^
    )
    ^
  File "/Users/utkan.basurgan/Main/1. Works Files/2. Gits Works/Zenarth-Meta-Hackathon-2025/APP_Api/venv/lib/python3.14/site-packages/paramiko/client.py", line 449, in connect
    t.start_client(timeout=timeout)
    ~~~~~~~~~~~~~~^^^^^^^^^^^^^^^^^
  File "/Users/utkan.basurgan/Main/1. Works Files/2. Gits Works/Zenarth-Meta-Hackathon-2025/APP_Api/venv/lib/python3.14/site-packages/paramiko/transport.py", line 768, in start_client
    raise e
  File "/Users/utkan.basurgan/Main/1. Works Files/2. Gits Works/Zenarth-Meta-Hackathon-2025/APP_Api/venv/lib/python3.14/site-packages/paramiko/transport.py", line 2179, in run
    self._check_banner()
    ~~~~~~~~~~~~~~~~~~^^
  File "/Users/utkan.basurgan/Main/1. Works Files/2. Gits Works/Zenarth-Meta-Hackathon-2025/APP_Api/venv/lib/python3.14/site-packages/paramiko/transport.py", line 2367, in _check_banner
    raise SSHException(
        "Error reading SSH protocol banner" + str(e)
    )
paramiko.ssh_exception.SSHException: Error reading SSH protocol banner

During handling of the above exception, another exception occurred:

Traceback (most recent call last):
  File "/Users/utkan.basurgan/Main/1. Works Files/2. Gits Works/Zenarth-Meta-Hackathon-2025/APP_Api/main_api.py", line 26, in <module>
    ssh = connect_ssh(HOST, PORT, USER, KEY_PATH, PASSFILE_PATH)
  File "/Users/utkan.basurgan/Main/1. Works Files/2. Gits Works/Zenarth-Meta-Hackathon-2025/APP_Api/python_api.py", line 52, in connect_ssh
    raise RuntimeError(f"SSH bağlantı hatası: {e}")
RuntimeError: SSH bağlantı hatası: Error reading SSH protocol banner

Return code: 1
Running main_api.py at 2025-10-25 23:37:51
Error: Exception (client): Error reading SSH protocol banner
Traceback (most recent call last):
  File "/Users/utkan.basurgan/Main/1. Works Files/2. Gits Works/Zenarth-Meta-Hackathon-2025/APP_Api/venv/lib/python3.14/site-packages/paramiko/transport.py", line 2363, in _check_banner
    buf = self.packetizer.readline(timeout)
  File "/Users/utkan.basurgan/Main/1. Works Files/2. Gits Works/Zenarth-Meta-Hackathon-2025/APP_Api/venv/lib/python3.14/site-packages/paramiko/packet.py", line 395, in readline
    buf += self._read_timeout(timeout)
           ~~~~~~~~~~~~~~~~~~^^^^^^^^^
  File "/Users/utkan.basurgan/Main/1. Works Files/2. Gits Works/Zenarth-Meta-Hackathon-2025/APP_Api/venv/lib/python3.14/site-packages/paramiko/packet.py", line 673, in _read_timeout
    raise socket.timeout()
TimeoutError

During handling of the above exception, another exception occurred:

Traceback (most recent call last):
  File "/Users/utkan.basurgan/Main/1. Works Files/2. Gits Works/Zenarth-Meta-Hackathon-2025/APP_Api/venv/lib/python3.14/site-packages/paramiko/transport.py", line 2179, in run
    self._check_banner()
    ~~~~~~~~~~~~~~~~~~^^
  File "/Users/utkan.basurgan/Main/1. Works Files/2. Gits Works/Zenarth-Meta-Hackathon-2025/APP_Api/venv/lib/python3.14/site-packages/paramiko/transport.py", line 2367, in _check_banner
    raise SSHException(
        "Error reading SSH protocol banner" + str(e)
    )
paramiko.ssh_exception.SSHException: Error reading SSH protocol banner

Traceback (most recent call last):
  File "/Users/utkan.basurgan/Main/1. Works Files/2. Gits Works/Zenarth-Meta-Hackathon-2025/APP_Api/venv/lib/python3.14/site-packages/paramiko/transport.py", line 2363, in _check_banner
    buf = self.packetizer.readline(timeout)
  File "/Users/utkan.basurgan/Main/1. Works Files/2. Gits Works/Zenarth-Meta-Hackathon-2025/APP_Api/venv/lib/python3.14/site-packages/paramiko/packet.py", line 395, in readline
    buf += self._read_timeout(timeout)
           ~~~~~~~~~~~~~~~~~~^^^^^^^^^
  File "/Users/utkan.basurgan/Main/1. Works Files/2. Gits Works/Zenarth-Meta-Hackathon-2025/APP_Api/venv/lib/python3.14/site-packages/paramiko/packet.py", line 673, in _read_timeout
    raise socket.timeout()
TimeoutError

During handling of the above exception, another exception occurred:

Traceback (most recent call last):
  File "/Users/utkan.basurgan/Main/1. Works Files/2. Gits Works/Zenarth-Meta-Hackathon-2025/APP_Api/python_api.py", line 42, in connect_ssh
    client.connect(
    ~~~~~~~~~~~~~~^
        hostname=host,
        ^^^^^^^^^^^^^^
    ...<5 lines>...
        look_for_keys=False,
        ^^^^^^^^^^^^^^^^^^^^
    )
    ^
  File "/Users/utkan.basurgan/Main/1. Works Files/2. Gits Works/Zenarth-Meta-Hackathon-2025/APP_Api/venv/lib/python3.14/site-packages/paramiko/client.py", line 449, in connect
    t.start_client(timeout=timeout)
    ~~~~~~~~~~~~~~^^^^^^^^^^^^^^^^^
  File "/Users/utkan.basurgan/Main/1. Works Files/2. Gits Works/Zenarth-Meta-Hackathon-2025/APP_Api/venv/lib/python3.14/site-packages/paramiko/transport.py", line 768, in start_client
    raise e
  File "/Users/utkan.basurgan/Main/1. Works Files/2. Gits Works/Zenarth-Meta-Hackathon-2025/APP_Api/venv/lib/python3.14/site-packages/paramiko/transport.py", line 2179, in run
    self._check_banner()
    ~~~~~~~~~~~~~~~~~~^^
  File "/Users/utkan.basurgan/Main/1. Works Files/2. Gits Works/Zenarth-Meta-Hackathon-2025/APP_Api/venv/lib/python3.14/site-packages/paramiko/transport.py", line 2367, in _check_banner
    raise SSHException(
        "Error reading SSH protocol banner" + str(e)
    )
paramiko.ssh_exception.SSHException: Error reading SSH protocol banner

During handling of the above exception, another exception occurred:

Traceback (most recent call last):
  File "/Users/utkan.basurgan/Main/1. Works Files/2. Gits Works/Zenarth-Meta-Hackathon-2025/APP_Api/main_api.py", line 26, in <module>
    ssh = connect_ssh(HOST, PORT, USER, KEY_PATH, PASSFILE_PATH)
  File "/Users/utkan.basurgan/Main/1. Works Files/2. Gits Works/Zenarth-Meta-Hackathon-2025/APP_Api/python_api.py", line 52, in connect_ssh
    raise RuntimeError(f"SSH bağlantı hatası: {e}")
RuntimeError: SSH bağlantı hatası: Error reading SSH protocol banner

Return code: 1
Running main_api.py at 2025-10-25 23:38:17
Error: Exception (client): Error reading SSH protocol banner
Traceback (most recent call last):
  File "/Users/utkan.basurgan/Main/1. Works Files/2. Gits Works/Zenarth-Meta-Hackathon-2025/APP_Api/venv/lib/python3.14/site-packages/paramiko/transport.py", line 2363, in _check_banner
    buf = self.packetizer.readline(timeout)
  File "/Users/utkan.basurgan/Main/1. Works Files/2. Gits Works/Zenarth-Meta-Hackathon-2025/APP_Api/venv/lib/python3.14/site-packages/paramiko/packet.py", line 395, in readline
    buf += self._read_timeout(timeout)
           ~~~~~~~~~~~~~~~~~~^^^^^^^^^
  File "/Users/utkan.basurgan/Main/1. Works Files/2. Gits Works/Zenarth-Meta-Hackathon-2025/APP_Api/venv/lib/python3.14/site-packages/paramiko/packet.py", line 673, in _read_timeout
    raise socket.timeout()
TimeoutError

During handling of the above exception, another exception occurred:

Traceback (most recent call last):
  File "/Users/utkan.basurgan/Main/1. Works Files/2. Gits Works/Zenarth-Meta-Hackathon-2025/APP_Api/venv/lib/python3.14/site-packages/paramiko/transport.py", line 2179, in run
    self._check_banner()
    ~~~~~~~~~~~~~~~~~~^^
  File "/Users/utkan.basurgan/Main/1. Works Files/2. Gits Works/Zenarth-Meta-Hackathon-2025/APP_Api/venv/lib/python3.14/site-packages/paramiko/transport.py", line 2367, in _check_banner
    raise SSHException(
        "Error reading SSH protocol banner" + str(e)
    )
paramiko.ssh_exception.SSHException: Error reading SSH protocol banner

Traceback (most recent call last):
  File "/Users/utkan.basurgan/Main/1. Works Files/2. Gits Works/Zenarth-Meta-Hackathon-2025/APP_Api/venv/lib/python3.14/site-packages/paramiko/transport.py", line 2363, in _check_banner
    buf = self.packetizer.readline(timeout)
  File "/Users/utkan.basurgan/Main/1. Works Files/2. Gits Works/Zenarth-Meta-Hackathon-2025/APP_Api/venv/lib/python3.14/site-packages/paramiko/packet.py", line 395, in readline
    buf += self._read_timeout(timeout)
           ~~~~~~~~~~~~~~~~~~^^^^^^^^^
  File "/Users/utkan.basurgan/Main/1. Works Files/2. Gits Works/Zenarth-Meta-Hackathon-2025/APP_Api/venv/lib/python3.14/site-packages/paramiko/packet.py", line 673, in _read_timeout
    raise socket.timeout()
TimeoutError

During handling of the above exception, another exception occurred:

Traceback (most recent call last):
  File "/Users/utkan.basurgan/Main/1. Works Files/2. Gits Works/Zenarth-Meta-Hackathon-2025/APP_Api/python_api.py", line 42, in connect_ssh
    client.connect(
    ~~~~~~~~~~~~~~^
        hostname=host,
        ^^^^^^^^^^^^^^
    ...<5 lines>...
        look_for_keys=False,
        ^^^^^^^^^^^^^^^^^^^^
    )
    ^
  File "/Users/utkan.basurgan/Main/1. Works Files/2. Gits Works/Zenarth-Meta-Hackathon-2025/APP_Api/venv/lib/python3.14/site-packages/paramiko/client.py", line 449, in connect
    t.start_client(timeout=timeout)
    ~~~~~~~~~~~~~~^^^^^^^^^^^^^^^^^
  File "/Users/utkan.basurgan/Main/1. Works Files/2. Gits Works/Zenarth-Meta-Hackathon-2025/APP_Api/venv/lib/python3.14/site-packages/paramiko/transport.py", line 768, in start_client
    raise e
  File "/Users/utkan.basurgan/Main/1. Works Files/2. Gits Works/Zenarth-Meta-Hackathon-2025/APP_Api/venv/lib/python3.14/site-packages/paramiko/transport.py", line 2179, in run
    self._check_banner()
    ~~~~~~~~~~~~~~~~~~^^
  File "/Users/utkan.basurgan/Main/1. Works Files/2. Gits Works/Zenarth-Meta-Hackathon-2025/APP_Api/venv/lib/python3.14/site-packages/paramiko/transport.py", line 2367, in _check_banner
    raise SSHException(
        "Error reading SSH protocol banner" + str(e)
    )
paramiko.ssh_exception.SSHException: Error reading SSH protocol banner

During handling of the above exception, another exception occurred:

Traceback (most recent call last):
  File "/Users/utkan.basurgan/Main/1. Works Files/2. Gits Works/Zenarth-Meta-Hackathon-2025/APP_Api/main_api.py", line 26, in <module>
    ssh = connect_ssh(HOST, PORT, USER, KEY_PATH, PASSFILE_PATH)
  File "/Users/utkan.basurgan/Main/1. Works Files/2. Gits Works/Zenarth-Meta-Hackathon-2025/APP_Api/python_api.py", line 52, in connect_ssh
    raise RuntimeError(f"SSH bağlantı hatası: {e}")
RuntimeError: SSH bağlantı hatası: Error reading SSH protocol banner

Return code: 1
Running main_api.py at 2025-10-25 23:38:42
Error: Exception (client): Error reading SSH protocol banner
Traceback (most recent call last):
  File "/Users/utkan.basurgan/Main/1. Works Files/2. Gits Works/Zenarth-Meta-Hackathon-2025/APP_Api/venv/lib/python3.14/site-packages/paramiko/transport.py", line 2363, in _check_banner
    buf = self.packetizer.readline(timeout)
  File "/Users/utkan.basurgan/Main/1. Works Files/2. Gits Works/Zenarth-Meta-Hackathon-2025/APP_Api/venv/lib/python3.14/site-packages/paramiko/packet.py", line 395, in readline
    buf += self._read_timeout(timeout)
           ~~~~~~~~~~~~~~~~~~^^^^^^^^^
  File "/Users/utkan.basurgan/Main/1. Works Files/2. Gits Works/Zenarth-Meta-Hackathon-2025/APP_Api/venv/lib/python3.14/site-packages/paramiko/packet.py", line 673, in _read_timeout
    raise socket.timeout()
TimeoutError

During handling of the above exception, another exception occurred:

Traceback (most recent call last):
  File "/Users/utkan.basurgan/Main/1. Works Files/2. Gits Works/Zenarth-Meta-Hackathon-2025/APP_Api/venv/lib/python3.14/site-packages/paramiko/transport.py", line 2179, in run
    self._check_banner()
    ~~~~~~~~~~~~~~~~~~^^
  File "/Users/utkan.basurgan/Main/1. Works Files/2. Gits Works/Zenarth-Meta-Hackathon-2025/APP_Api/venv/lib/python3.14/site-packages/paramiko/transport.py", line 2367, in _check_banner
    raise SSHException(
        "Error reading SSH protocol banner" + str(e)
    )
paramiko.ssh_exception.SSHException: Error reading SSH protocol banner

Traceback (most recent call last):
  File "/Users/utkan.basurgan/Main/1. Works Files/2. Gits Works/Zenarth-Meta-Hackathon-2025/APP_Api/venv/lib/python3.14/site-packages/paramiko/transport.py", line 2363, in _check_banner
    buf = self.packetizer.readline(timeout)
  File "/Users/utkan.basurgan/Main/1. Works Files/2. Gits Works/Zenarth-Meta-Hackathon-2025/APP_Api/venv/lib/python3.14/site-packages/paramiko/packet.py", line 395, in readline
    buf += self._read_timeout(timeout)
           ~~~~~~~~~~~~~~~~~~^^^^^^^^^
  File "/Users/utkan.basurgan/Main/1. Works Files/2. Gits Works/Zenarth-Meta-Hackathon-2025/APP_Api/venv/lib/python3.14/site-packages/paramiko/packet.py", line 673, in _read_timeout
    raise socket.timeout()
TimeoutError

During handling of the above exception, another exception occurred:

Traceback (most recent call last):
  File "/Users/utkan.basurgan/Main/1. Works Files/2. Gits Works/Zenarth-Meta-Hackathon-2025/APP_Api/python_api.py", line 42, in connect_ssh
    client.connect(
    ~~~~~~~~~~~~~~^
        hostname=host,
        ^^^^^^^^^^^^^^
    ...<5 lines>...
        look_for_keys=False,
        ^^^^^^^^^^^^^^^^^^^^
    )
    ^
  File "/Users/utkan.basurgan/Main/1. Works Files/2. Gits Works/Zenarth-Meta-Hackathon-2025/APP_Api/venv/lib/python3.14/site-packages/paramiko/client.py", line 449, in connect
    t.start_client(timeout=timeout)
    ~~~~~~~~~~~~~~^^^^^^^^^^^^^^^^^
  File "/Users/utkan.basurgan/Main/1. Works Files/2. Gits Works/Zenarth-Meta-Hackathon-2025/APP_Api/venv/lib/python3.14/site-packages/paramiko/transport.py", line 768, in start_client
    raise e
  File "/Users/utkan.basurgan/Main/1. Works Files/2. Gits Works/Zenarth-Meta-Hackathon-2025/APP_Api/venv/lib/python3.14/site-packages/paramiko/transport.py", line 2179, in run
    self._check_banner()
    ~~~~~~~~~~~~~~~~~~^^
  File "/Users/utkan.basurgan/Main/1. Works Files/2. Gits Works/Zenarth-Meta-Hackathon-2025/APP_Api/venv/lib/python3.14/site-packages/paramiko/transport.py", line 2367, in _check_banner
    raise SSHException(
        "Error reading SSH protocol banner" + str(e)
    )
paramiko.ssh_exception.SSHException: Error reading SSH protocol banner

During handling of the above exception, another exception occurred:

Traceback (most recent call last):
  File "/Users/utkan.basurgan/Main/1. Works Files/2. Gits Works/Zenarth-Meta-Hackathon-2025/APP_Api/main_api.py", line 26, in <module>
    ssh = connect_ssh(HOST, PORT, USER, KEY_PATH, PASSFILE_PATH)
  File "/Users/utkan.basurgan/Main/1. Works Files/2. Gits Works/Zenarth-Meta-Hackathon-2025/APP_Api/python_api.py", line 52, in connect_ssh
    raise RuntimeError(f"SSH bağlantı hatası: {e}")
RuntimeError: SSH bağlantı hatası: Error reading SSH protocol banner

Return code: 1
Running main_api.py at 2025-10-25 23:39:08
Error: Exception (client): Error reading SSH protocol banner
Traceback (most recent call last):
  File "/Users/utkan.basurgan/Main/1. Works Files/2. Gits Works/Zenarth-Meta-Hackathon-2025/APP_Api/venv/lib/python3.14/site-packages/paramiko/transport.py", line 2363, in _check_banner
    buf = self.packetizer.readline(timeout)
  File "/Users/utkan.basurgan/Main/1. Works Files/2. Gits Works/Zenarth-Meta-Hackathon-2025/APP_Api/venv/lib/python3.14/site-packages/paramiko/packet.py", line 395, in readline
    buf += self._read_timeout(timeout)
           ~~~~~~~~~~~~~~~~~~^^^^^^^^^
  File "/Users/utkan.basurgan/Main/1. Works Files/2. Gits Works/Zenarth-Meta-Hackathon-2025/APP_Api/venv/lib/python3.14/site-packages/paramiko/packet.py", line 673, in _read_timeout
    raise socket.timeout()
TimeoutError

During handling of the above exception, another exception occurred:

Traceback (most recent call last):
  File "/Users/utkan.basurgan/Main/1. Works Files/2. Gits Works/Zenarth-Meta-Hackathon-2025/APP_Api/venv/lib/python3.14/site-packages/paramiko/transport.py", line 2179, in run
    self._check_banner()
    ~~~~~~~~~~~~~~~~~~^^
  File "/Users/utkan.basurgan/Main/1. Works Files/2. Gits Works/Zenarth-Meta-Hackathon-2025/APP_Api/venv/lib/python3.14/site-packages/paramiko/transport.py", line 2367, in _check_banner
    raise SSHException(
        "Error reading SSH protocol banner" + str(e)
    )
paramiko.ssh_exception.SSHException: Error reading SSH protocol banner

Traceback (most recent call last):
  File "/Users/utkan.basurgan/Main/1. Works Files/2. Gits Works/Zenarth-Meta-Hackathon-2025/APP_Api/venv/lib/python3.14/site-packages/paramiko/transport.py", line 2363, in _check_banner
    buf = self.packetizer.readline(timeout)
  File "/Users/utkan.basurgan/Main/1. Works Files/2. Gits Works/Zenarth-Meta-Hackathon-2025/APP_Api/venv/lib/python3.14/site-packages/paramiko/packet.py", line 395, in readline
    buf += self._read_timeout(timeout)
           ~~~~~~~~~~~~~~~~~~^^^^^^^^^
  File "/Users/utkan.basurgan/Main/1. Works Files/2. Gits Works/Zenarth-Meta-Hackathon-2025/APP_Api/venv/lib/python3.14/site-packages/paramiko/packet.py", line 673, in _read_timeout
    raise socket.timeout()
TimeoutError

During handling of the above exception, another exception occurred:

Traceback (most recent call last):
  File "/Users/utkan.basurgan/Main/1. Works Files/2. Gits Works/Zenarth-Meta-Hackathon-2025/APP_Api/python_api.py", line 42, in connect_ssh
    client.connect(
    ~~~~~~~~~~~~~~^
        hostname=host,
        ^^^^^^^^^^^^^^
    ...<5 lines>...
        look_for_keys=False,
        ^^^^^^^^^^^^^^^^^^^^
    )
    ^
  File "/Users/utkan.basurgan/Main/1. Works Files/2. Gits Works/Zenarth-Meta-Hackathon-2025/APP_Api/venv/lib/python3.14/site-packages/paramiko/client.py", line 449, in connect
    t.start_client(timeout=timeout)
    ~~~~~~~~~~~~~~^^^^^^^^^^^^^^^^^
  File "/Users/utkan.basurgan/Main/1. Works Files/2. Gits Works/Zenarth-Meta-Hackathon-2025/APP_Api/venv/lib/python3.14/site-packages/paramiko/transport.py", line 768, in start_client
    raise e
  File "/Users/utkan.basurgan/Main/1. Works Files/2. Gits Works/Zenarth-Meta-Hackathon-2025/APP_Api/venv/lib/python3.14/site-packages/paramiko/transport.py", line 2179, in run
    self._check_banner()
    ~~~~~~~~~~~~~~~~~~^^
  File "/Users/utkan.basurgan/Main/1. Works Files/2. Gits Works/Zenarth-Meta-Hackathon-2025/APP_Api/venv/lib/python3.14/site-packages/paramiko/transport.py", line 2367, in _check_banner
    raise SSHException(
        "Error reading SSH protocol banner" + str(e)
    )
paramiko.ssh_exception.SSHException: Error reading SSH protocol banner

During handling of the above exception, another exception occurred:

Traceback (most recent call last):
  File "/Users/utkan.basurgan/Main/1. Works Files/2. Gits Works/Zenarth-Meta-Hackathon-2025/APP_Api/main_api.py", line 26, in <module>
    ssh = connect_ssh(HOST, PORT, USER, KEY_PATH, PASSFILE_PATH)
  File "/Users/utkan.basurgan/Main/1. Works Files/2. Gits Works/Zenarth-Meta-Hackathon-2025/APP_Api/python_api.py", line 52, in connect_ssh
    raise RuntimeError(f"SSH bağlantı hatası: {e}")
RuntimeError: SSH bağlantı hatası: Error reading SSH protocol banner

Return code: 1
Running main_api.py at 2025-10-25 23:39:34
Error: Exception (client): Error reading SSH protocol banner
Traceback (most recent call last):
  File "/Users/utkan.basurgan/Main/1. Works Files/2. Gits Works/Zenarth-Meta-Hackathon-2025/APP_Api/venv/lib/python3.14/site-packages/paramiko/transport.py", line 2363, in _check_banner
    buf = self.packetizer.readline(timeout)
  File "/Users/utkan.basurgan/Main/1. Works Files/2. Gits Works/Zenarth-Meta-Hackathon-2025/APP_Api/venv/lib/python3.14/site-packages/paramiko/packet.py", line 395, in readline
    buf += self._read_timeout(timeout)
           ~~~~~~~~~~~~~~~~~~^^^^^^^^^
  File "/Users/utkan.basurgan/Main/1. Works Files/2. Gits Works/Zenarth-Meta-Hackathon-2025/APP_Api/venv/lib/python3.14/site-packages/paramiko/packet.py", line 673, in _read_timeout
    raise socket.timeout()
TimeoutError

During handling of the above exception, another exception occurred:

Traceback (most recent call last):
  File "/Users/utkan.basurgan/Main/1. Works Files/2. Gits Works/Zenarth-Meta-Hackathon-2025/APP_Api/venv/lib/python3.14/site-packages/paramiko/transport.py", line 2179, in run
    self._check_banner()
    ~~~~~~~~~~~~~~~~~~^^
  File "/Users/utkan.basurgan/Main/1. Works Files/2. Gits Works/Zenarth-Meta-Hackathon-2025/APP_Api/venv/lib/python3.14/site-packages/paramiko/transport.py", line 2367, in _check_banner
    raise SSHException(
        "Error reading SSH protocol banner" + str(e)
    )
paramiko.ssh_exception.SSHException: Error reading SSH protocol banner

Traceback (most recent call last):
  File "/Users/utkan.basurgan/Main/1. Works Files/2. Gits Works/Zenarth-Meta-Hackathon-2025/APP_Api/venv/lib/python3.14/site-packages/paramiko/transport.py", line 2363, in _check_banner
    buf = self.packetizer.readline(timeout)
  File "/Users/utkan.basurgan/Main/1. Works Files/2. Gits Works/Zenarth-Meta-Hackathon-2025/APP_Api/venv/lib/python3.14/site-packages/paramiko/packet.py", line 395, in readline
    buf += self._read_timeout(timeout)
           ~~~~~~~~~~~~~~~~~~^^^^^^^^^
  File "/Users/utkan.basurgan/Main/1. Works Files/2. Gits Works/Zenarth-Meta-Hackathon-2025/APP_Api/venv/lib/python3.14/site-packages/paramiko/packet.py", line 673, in _read_timeout
    raise socket.timeout()
TimeoutError

During handling of the above exception, another exception occurred:

Traceback (most recent call last):
  File "/Users/utkan.basurgan/Main/1. Works Files/2. Gits Works/Zenarth-Meta-Hackathon-2025/APP_Api/python_api.py", line 42, in connect_ssh
    client.connect(
    ~~~~~~~~~~~~~~^
        hostname=host,
        ^^^^^^^^^^^^^^
    ...<5 lines>...
        look_for_keys=False,
        ^^^^^^^^^^^^^^^^^^^^
    )
    ^
  File "/Users/utkan.basurgan/Main/1. Works Files/2. Gits Works/Zenarth-Meta-Hackathon-2025/APP_Api/venv/lib/python3.14/site-packages/paramiko/client.py", line 449, in connect
    t.start_client(timeout=timeout)
    ~~~~~~~~~~~~~~^^^^^^^^^^^^^^^^^
  File "/Users/utkan.basurgan/Main/1. Works Files/2. Gits Works/Zenarth-Meta-Hackathon-2025/APP_Api/venv/lib/python3.14/site-packages/paramiko/transport.py", line 768, in start_client
    raise e
  File "/Users/utkan.basurgan/Main/1. Works Files/2. Gits Works/Zenarth-Meta-Hackathon-2025/APP_Api/venv/lib/python3.14/site-packages/paramiko/transport.py", line 2179, in run
    self._check_banner()
    ~~~~~~~~~~~~~~~~~~^^
  File "/Users/utkan.basurgan/Main/1. Works Files/2. Gits Works/Zenarth-Meta-Hackathon-2025/APP_Api/venv/lib/python3.14/site-packages/paramiko/transport.py", line 2367, in _check_banner
    raise SSHException(
        "Error reading SSH protocol banner" + str(e)
    )
paramiko.ssh_exception.SSHException: Error reading SSH protocol banner

During handling of the above exception, another exception occurred:

Traceback (most recent call last):
  File "/Users/utkan.basurgan/Main/1. Works Files/2. Gits Works/Zenarth-Meta-Hackathon-2025/APP_Api/main_api.py", line 26, in <module>
    ssh = connect_ssh(HOST, PORT, USER, KEY_PATH, PASSFILE_PATH)
  File "/Users/utkan.basurgan/Main/1. Works Files/2. Gits Works/Zenarth-Meta-Hackathon-2025/APP_Api/python_api.py", line 52, in connect_ssh
    raise RuntimeError(f"SSH bağlantı hatası: {e}")
RuntimeError: SSH bağlantı hatası: Error reading SSH protocol banner

Return code: 1
Running main_api.py at 2025-10-25 23:40:00
Error: Exception (client): Error reading SSH protocol banner
Traceback (most recent call last):
  File "/Users/utkan.basurgan/Main/1. Works Files/2. Gits Works/Zenarth-Meta-Hackathon-2025/APP_Api/venv/lib/python3.14/site-packages/paramiko/transport.py", line 2363, in _check_banner
    buf = self.packetizer.readline(timeout)
  File "/Users/utkan.basurgan/Main/1. Works Files/2. Gits Works/Zenarth-Meta-Hackathon-2025/APP_Api/venv/lib/python3.14/site-packages/paramiko/packet.py", line 395, in readline
    buf += self._read_timeout(timeout)
           ~~~~~~~~~~~~~~~~~~^^^^^^^^^
  File "/Users/utkan.basurgan/Main/1. Works Files/2. Gits Works/Zenarth-Meta-Hackathon-2025/APP_Api/venv/lib/python3.14/site-packages/paramiko/packet.py", line 673, in _read_timeout
    raise socket.timeout()
TimeoutError

During handling of the above exception, another exception occurred:

Traceback (most recent call last):
  File "/Users/utkan.basurgan/Main/1. Works Files/2. Gits Works/Zenarth-Meta-Hackathon-2025/APP_Api/venv/lib/python3.14/site-packages/paramiko/transport.py", line 2179, in run
    self._check_banner()
    ~~~~~~~~~~~~~~~~~~^^
  File "/Users/utkan.basurgan/Main/1. Works Files/2. Gits Works/Zenarth-Meta-Hackathon-2025/APP_Api/venv/lib/python3.14/site-packages/paramiko/transport.py", line 2367, in _check_banner
    raise SSHException(
        "Error reading SSH protocol banner" + str(e)
    )
paramiko.ssh_exception.SSHException: Error reading SSH protocol banner

Traceback (most recent call last):
  File "/Users/utkan.basurgan/Main/1. Works Files/2. Gits Works/Zenarth-Meta-Hackathon-2025/APP_Api/venv/lib/python3.14/site-packages/paramiko/transport.py", line 2363, in _check_banner
    buf = self.packetizer.readline(timeout)
  File "/Users/utkan.basurgan/Main/1. Works Files/2. Gits Works/Zenarth-Meta-Hackathon-2025/APP_Api/venv/lib/python3.14/site-packages/paramiko/packet.py", line 395, in readline
    buf += self._read_timeout(timeout)
           ~~~~~~~~~~~~~~~~~~^^^^^^^^^
  File "/Users/utkan.basurgan/Main/1. Works Files/2. Gits Works/Zenarth-Meta-Hackathon-2025/APP_Api/venv/lib/python3.14/site-packages/paramiko/packet.py", line 673, in _read_timeout
    raise socket.timeout()
TimeoutError

During handling of the above exception, another exception occurred:

Traceback (most recent call last):
  File "/Users/utkan.basurgan/Main/1. Works Files/2. Gits Works/Zenarth-Meta-Hackathon-2025/APP_Api/python_api.py", line 42, in connect_ssh
    client.connect(
    ~~~~~~~~~~~~~~^
        hostname=host,
        ^^^^^^^^^^^^^^
    ...<5 lines>...
        look_for_keys=False,
        ^^^^^^^^^^^^^^^^^^^^
    )
    ^
  File "/Users/utkan.basurgan/Main/1. Works Files/2. Gits Works/Zenarth-Meta-Hackathon-2025/APP_Api/venv/lib/python3.14/site-packages/paramiko/client.py", line 449, in connect
    t.start_client(timeout=timeout)
    ~~~~~~~~~~~~~~^^^^^^^^^^^^^^^^^
  File "/Users/utkan.basurgan/Main/1. Works Files/2. Gits Works/Zenarth-Meta-Hackathon-2025/APP_Api/venv/lib/python3.14/site-packages/paramiko/transport.py", line 768, in start_client
    raise e
  File "/Users/utkan.basurgan/Main/1. Works Files/2. Gits Works/Zenarth-Meta-Hackathon-2025/APP_Api/venv/lib/python3.14/site-packages/paramiko/transport.py", line 2179, in run
    self._check_banner()
    ~~~~~~~~~~~~~~~~~~^^
  File "/Users/utkan.basurgan/Main/1. Works Files/2. Gits Works/Zenarth-Meta-Hackathon-2025/APP_Api/venv/lib/python3.14/site-packages/paramiko/transport.py", line 2367, in _check_banner
    raise SSHException(
        "Error reading SSH protocol banner" + str(e)
    )
paramiko.ssh_exception.SSHException: Error reading SSH protocol banner

During handling of the above exception, another exception occurred:

Traceback (most recent call last):
  File "/Users/utkan.basurgan/Main/1. Works Files/2. Gits Works/Zenarth-Meta-Hackathon-2025/APP_Api/main_api.py", line 26, in <module>
    ssh = connect_ssh(HOST, PORT, USER, KEY_PATH, PASSFILE_PATH)
  File "/Users/utkan.basurgan/Main/1. Works Files/2. Gits Works/Zenarth-Meta-Hackathon-2025/APP_Api/python_api.py", line 52, in connect_ssh
    raise RuntimeError(f"SSH bağlantı hatası: {e}")
RuntimeError: SSH bağlantı hatası: Error reading SSH protocol banner

Return code: 1
Running main_api.py at 2025-10-25 23:40:26
Error: Exception (client): Error reading SSH protocol banner
Traceback (most recent call last):
  File "/Users/utkan.basurgan/Main/1. Works Files/2. Gits Works/Zenarth-Meta-Hackathon-2025/APP_Api/venv/lib/python3.14/site-packages/paramiko/transport.py", line 2363, in _check_banner
    buf = self.packetizer.readline(timeout)
  File "/Users/utkan.basurgan/Main/1. Works Files/2. Gits Works/Zenarth-Meta-Hackathon-2025/APP_Api/venv/lib/python3.14/site-packages/paramiko/packet.py", line 395, in readline
    buf += self._read_timeout(timeout)
           ~~~~~~~~~~~~~~~~~~^^^^^^^^^
  File "/Users/utkan.basurgan/Main/1. Works Files/2. Gits Works/Zenarth-Meta-Hackathon-2025/APP_Api/venv/lib/python3.14/site-packages/paramiko/packet.py", line 673, in _read_timeout
    raise socket.timeout()
TimeoutError

During handling of the above exception, another exception occurred:

Traceback (most recent call last):
  File "/Users/utkan.basurgan/Main/1. Works Files/2. Gits Works/Zenarth-Meta-Hackathon-2025/APP_Api/venv/lib/python3.14/site-packages/paramiko/transport.py", line 2179, in run
    self._check_banner()
    ~~~~~~~~~~~~~~~~~~^^
  File "/Users/utkan.basurgan/Main/1. Works Files/2. Gits Works/Zenarth-Meta-Hackathon-2025/APP_Api/venv/lib/python3.14/site-packages/paramiko/transport.py", line 2367, in _check_banner
    raise SSHException(
        "Error reading SSH protocol banner" + str(e)
    )
paramiko.ssh_exception.SSHException: Error reading SSH protocol banner

Traceback (most recent call last):
  File "/Users/utkan.basurgan/Main/1. Works Files/2. Gits Works/Zenarth-Meta-Hackathon-2025/APP_Api/venv/lib/python3.14/site-packages/paramiko/transport.py", line 2363, in _check_banner
    buf = self.packetizer.readline(timeout)
  File "/Users/utkan.basurgan/Main/1. Works Files/2. Gits Works/Zenarth-Meta-Hackathon-2025/APP_Api/venv/lib/python3.14/site-packages/paramiko/packet.py", line 395, in readline
    buf += self._read_timeout(timeout)
           ~~~~~~~~~~~~~~~~~~^^^^^^^^^
  File "/Users/utkan.basurgan/Main/1. Works Files/2. Gits Works/Zenarth-Meta-Hackathon-2025/APP_Api/venv/lib/python3.14/site-packages/paramiko/packet.py", line 673, in _read_timeout
    raise socket.timeout()
TimeoutError

During handling of the above exception, another exception occurred:

Traceback (most recent call last):
  File "/Users/utkan.basurgan/Main/1. Works Files/2. Gits Works/Zenarth-Meta-Hackathon-2025/APP_Api/python_api.py", line 42, in connect_ssh
    client.connect(
    ~~~~~~~~~~~~~~^
        hostname=host,
        ^^^^^^^^^^^^^^
    ...<5 lines>...
        look_for_keys=False,
        ^^^^^^^^^^^^^^^^^^^^
    )
    ^
  File "/Users/utkan.basurgan/Main/1. Works Files/2. Gits Works/Zenarth-Meta-Hackathon-2025/APP_Api/venv/lib/python3.14/site-packages/paramiko/client.py", line 449, in connect
    t.start_client(timeout=timeout)
    ~~~~~~~~~~~~~~^^^^^^^^^^^^^^^^^
  File "/Users/utkan.basurgan/Main/1. Works Files/2. Gits Works/Zenarth-Meta-Hackathon-2025/APP_Api/venv/lib/python3.14/site-packages/paramiko/transport.py", line 768, in start_client
    raise e
  File "/Users/utkan.basurgan/Main/1. Works Files/2. Gits Works/Zenarth-Meta-Hackathon-2025/APP_Api/venv/lib/python3.14/site-packages/paramiko/transport.py", line 2179, in run
    self._check_banner()
    ~~~~~~~~~~~~~~~~~~^^
  File "/Users/utkan.basurgan/Main/1. Works Files/2. Gits Works/Zenarth-Meta-Hackathon-2025/APP_Api/venv/lib/python3.14/site-packages/paramiko/transport.py", line 2367, in _check_banner
    raise SSHException(
        "Error reading SSH protocol banner" + str(e)
    )
paramiko.ssh_exception.SSHException: Error reading SSH protocol banner

During handling of the above exception, another exception occurred:

Traceback (most recent call last):
  File "/Users/utkan.basurgan/Main/1. Works Files/2. Gits Works/Zenarth-Meta-Hackathon-2025/APP_Api/main_api.py", line 26, in <module>
    ssh = connect_ssh(HOST, PORT, USER, KEY_PATH, PASSFILE_PATH)
  File "/Users/utkan.basurgan/Main/1. Works Files/2. Gits Works/Zenarth-Meta-Hackathon-2025/APP_Api/python_api.py", line 52, in connect_ssh
    raise RuntimeError(f"SSH bağlantı hatası: {e}")
RuntimeError: SSH bağlantı hatası: Error reading SSH protocol banner

Return code: 1
Running main_api.py at 2025-10-25 23:40:51
Error: Exception (client): Error reading SSH protocol banner
Traceback (most recent call last):
  File "/Users/utkan.basurgan/Main/1. Works Files/2. Gits Works/Zenarth-Meta-Hackathon-2025/APP_Api/venv/lib/python3.14/site-packages/paramiko/transport.py", line 2363, in _check_banner
    buf = self.packetizer.readline(timeout)
  File "/Users/utkan.basurgan/Main/1. Works Files/2. Gits Works/Zenarth-Meta-Hackathon-2025/APP_Api/venv/lib/python3.14/site-packages/paramiko/packet.py", line 395, in readline
    buf += self._read_timeout(timeout)
           ~~~~~~~~~~~~~~~~~~^^^^^^^^^
  File "/Users/utkan.basurgan/Main/1. Works Files/2. Gits Works/Zenarth-Meta-Hackathon-2025/APP_Api/venv/lib/python3.14/site-packages/paramiko/packet.py", line 673, in _read_timeout
    raise socket.timeout()
TimeoutError

During handling of the above exception, another exception occurred:

Traceback (most recent call last):
  File "/Users/utkan.basurgan/Main/1. Works Files/2. Gits Works/Zenarth-Meta-Hackathon-2025/APP_Api/venv/lib/python3.14/site-packages/paramiko/transport.py", line 2179, in run
    self._check_banner()
    ~~~~~~~~~~~~~~~~~~^^
  File "/Users/utkan.basurgan/Main/1. Works Files/2. Gits Works/Zenarth-Meta-Hackathon-2025/APP_Api/venv/lib/python3.14/site-packages/paramiko/transport.py", line 2367, in _check_banner
    raise SSHException(
        "Error reading SSH protocol banner" + str(e)
    )
paramiko.ssh_exception.SSHException: Error reading SSH protocol banner

Traceback (most recent call last):
  File "/Users/utkan.basurgan/Main/1. Works Files/2. Gits Works/Zenarth-Meta-Hackathon-2025/APP_Api/venv/lib/python3.14/site-packages/paramiko/transport.py", line 2363, in _check_banner
    buf = self.packetizer.readline(timeout)
  File "/Users/utkan.basurgan/Main/1. Works Files/2. Gits Works/Zenarth-Meta-Hackathon-2025/APP_Api/venv/lib/python3.14/site-packages/paramiko/packet.py", line 395, in readline
    buf += self._read_timeout(timeout)
           ~~~~~~~~~~~~~~~~~~^^^^^^^^^
  File "/Users/utkan.basurgan/Main/1. Works Files/2. Gits Works/Zenarth-Meta-Hackathon-2025/APP_Api/venv/lib/python3.14/site-packages/paramiko/packet.py", line 673, in _read_timeout
    raise socket.timeout()
TimeoutError

During handling of the above exception, another exception occurred:

Traceback (most recent call last):
  File "/Users/utkan.basurgan/Main/1. Works Files/2. Gits Works/Zenarth-Meta-Hackathon-2025/APP_Api/python_api.py", line 42, in connect_ssh
    client.connect(
    ~~~~~~~~~~~~~~^
        hostname=host,
        ^^^^^^^^^^^^^^
    ...<5 lines>...
        look_for_keys=False,
        ^^^^^^^^^^^^^^^^^^^^
    )
    ^
  File "/Users/utkan.basurgan/Main/1. Works Files/2. Gits Works/Zenarth-Meta-Hackathon-2025/APP_Api/venv/lib/python3.14/site-packages/paramiko/client.py", line 449, in connect
    t.start_client(timeout=timeout)
    ~~~~~~~~~~~~~~^^^^^^^^^^^^^^^^^
  File "/Users/utkan.basurgan/Main/1. Works Files/2. Gits Works/Zenarth-Meta-Hackathon-2025/APP_Api/venv/lib/python3.14/site-packages/paramiko/transport.py", line 768, in start_client
    raise e
  File "/Users/utkan.basurgan/Main/1. Works Files/2. Gits Works/Zenarth-Meta-Hackathon-2025/APP_Api/venv/lib/python3.14/site-packages/paramiko/transport.py", line 2179, in run
    self._check_banner()
    ~~~~~~~~~~~~~~~~~~^^
  File "/Users/utkan.basurgan/Main/1. Works Files/2. Gits Works/Zenarth-Meta-Hackathon-2025/APP_Api/venv/lib/python3.14/site-packages/paramiko/transport.py", line 2367, in _check_banner
    raise SSHException(
        "Error reading SSH protocol banner" + str(e)
    )
paramiko.ssh_exception.SSHException: Error reading SSH protocol banner

During handling of the above exception, another exception occurred:

Traceback (most recent call last):
  File "/Users/utkan.basurgan/Main/1. Works Files/2. Gits Works/Zenarth-Meta-Hackathon-2025/APP_Api/main_api.py", line 26, in <module>
    ssh = connect_ssh(HOST, PORT, USER, KEY_PATH, PASSFILE_PATH)
  File "/Users/utkan.basurgan/Main/1. Works Files/2. Gits Works/Zenarth-Meta-Hackathon-2025/APP_Api/python_api.py", line 52, in connect_ssh
    raise RuntimeError(f"SSH bağlantı hatası: {e}")
RuntimeError: SSH bağlantı hatası: Error reading SSH protocol banner

Return code: 1
Running main_api.py at 2025-10-25 23:41:17
